Workbook

Sheet Sheet1
A4: EJECUTOR | B4: TITULO PROYECTO | C4: MANDANTE O TITULAR | D4: N° DE RESOLUCIÓN SUBPESCA
A5: BRIAN REID (CIEP) | B5: EFECTO DE SEDIMENTOS SUSPENDIDOS A LA ALIMENTACIÓN DE LOS PECES NATIVOS E INTRODUCIDOS, EN LA CUENCA DEL RÍO SIMPSON, REGIÓN DE AYSÉN | C5: Centro de Investigación de Ecosistemas de la Patagonia, CIEP | D5: R. EX N°E-2022-499
A6: Claudia Verdugo Castro | B6: Línea base limnológica Río Trainel cercano a la Piscicultura Trainel, Región de Los Lagos | C6: Piscicultura Trainel | D6: R. EX. N° E-2020-607
B7: Monitoreo Limnológico Proyecto Refundición de RCA's Amplición y Cambio Operacional, Río Petrohué, comuna de Puerto Varas, Región de Los Lagos | C7: Salmones Camanchaca S.A. | D7: R. EX N°65/2020
A8: CLAUDIA VERDUGO CASTRO (ECOSISTEMA) | B8: PISCICULTURA DE RECIRCULACIÓN LAGO BALMACEDA, SEALAND AQUACULTURE S.A. RESPUESTA OBSERVACIÓN 1.2.8 ICSARA N°1 (064/2016) | C8: SEALAND AQUACULTURE S.A. | D8: R.EX N°3232/2016
A9: Cultivos Marinos Lago Yelcho S.P.A. | B9: CARACTERIZACIÓN DE FAUNA ÍCTICA ASOCIADA AL PROYECTO, PISCICULTURA SAN JOAQUÍN. RIO CISNES, HUALAIHUÉ ESTERO, COMUNA DE HUALAIHUÉ, PROVINCIA DE PALENA. REGIÓN DE LOS LAGOS. | C9: Juan Cárcamo Barría | D9: R. EX N°411-2017
A10: GAMAN LIMNO STUDIES LTDA. | B10: CENTRAL HIDROELECTRICA CHAICA | C10: INGENIUM CIVIL S.A | D10: R.EX N°767/2014
A11: ICNOVA ING | B11: Proyecto de riego Magallanes, embalse río Porvenir | C11: Comisión Nacional de Riego | D11: R. EX N°838/2018
A12: ICNOVA ING CONSULTORES | B12: Diagnostico Hidrobiológico de Laguna Escondida y Laguna Barrosa - Declaración de Impacto Ambiental Almacenamiento de Agua de Interior Mina Javiera en Laguna Salitrosa, Comuna de Chile Chico, XII Región de Aysén | C12: Compañía Minera Cerro Bayo Ltda | D12: R. EX N°388/2018
A13: Jaime Illanes y Asociados Consultores S.A. | B13: Caracterización ecosistemas acuáticos continentales asociados al proyecto modificación piscicultura los Tilcos, Río Chico región de los Lagos | C13: Jaime Illanes y Asociados Consultores S.A. | D13: R. EX N°E-2021-074
A14: Maring EIRL | B14: Piscultura El Arco | C14: Garo S.A | D14: R.EX N°262/2012
A15: MARTINEZ AMBIENTAL LTDA | B15: MINA INVIERNO | C15: MINERA INVIERNO SA | D15: R.EX N°1628/2019
A16: PHOTOSINTESIS | B16: CARACTERIZACIÓN LIMNOLÓGICA Y USO DE HÁBITATS RIBEREÑOS EN LOS LAGOS MEULLÍN, YULTON Y RÍO CUERVOS, REGIÓN DEL GRAL. CARLOS IBÁÑEZ DEL CAMPO | C16: Orcas SpA | D16: R. EX N°E-2021-117
A17: Grand Total
D22: Permiso | E22: Referencia
A23: Brian Reid | B23: EFECTO DE SEDIMENTOS SUSPENDIDOS A LA ALIMENTACIÓN DE LOS PECES NATIVOS E INTRODUCIDOS, EN LA CUENCA DEL RÍO SIMPSON, REGIÓN DE AYSÉN | C23: Centro de Investigación de Ecosistemas de la Patagonia, CIEP | D23: R. EX N°E-2022-499 | E23: Brian Reid (2022) Informe de resutados de pesca de investigación asociado al permiso SUBPESCA, R. EX N°E-2022-499. Proyecto: Efecto de sedimentos suspendidos a la alimentación de los peces nativos e introducidos, en la cuenca del río Simpson, región de Aysén. Centro de Investigación de Ecosistemas de la Patagonia.
A24: Claudia Verdugo Castro | B24: Línea base limnológica Río Trainel cercano a la Piscicultura Trainel, Región de Los Lagos | C24: Piscicultura Trainel | D24: R. EX. N° E-2020-607 | E24: Claudia Verdugo Castro (2020) Informe de resutados de pesca de investigación asociado al permiso SUBPESCA, R. EX. N° E-2020-607 . Proyecto: Línea base limnológica Río Trainel cercano a la Piscicultura Trainel, región de Los Lagos. Mandante: Piscicultura Trainel.
B25: Monitoreo Limnológico Proyecto Refundición de RCA's Amplición y Cambio Operacional, Río Petrohué, comuna de Puerto Varas, Región de Los Lagos | C25: Salmones Camanchaca S.A. | D25: R. EX N°65/2020 | E25: Claudia Verdugo Castro (2020) Informe de resutados de pesca de investigación asociado al permiso SUBPESCA, R. EX N°65/2020. Proyecto: Monitoreo limnológico proyecto refundición de RCA's Amplición y cambio operacional, río Petrohué, comuna de Puerto Varas, región de Los Lagos. Mandante: Salmones Camanchaca S.A.
A26: CLAUDIA VERDUGO CASTRO (ECOSISTEMA) | B26: PISCICULTURA DE RECIRCULACIÓN LAGO BALMACEDA, SEALAND AQUACULTURE S.A. RESPUESTA OBSERVACIÓN 1.2.8 ICSARA N°1 (064/2016) | C26: SEALAND AQUACULTURE S.A. | D26: R.EX N°3232/2016 | E26: Claudia Verdugo Castro (Ecosistema) (2016) Informe de resutados de pesca de investigación asociado al permiso SUBPESCA, R.EX N°3232/2016. Proyecto: Piscicultura de recirculación lago Balmaceda, Sealand Aquaculture S.A.; respuesta observación 1.2.8 ICSARA n°1 (064/2016). Mandante: Sealand Aquaculture S.A.
A27: Cultivos Marinos Lago Yelcho S.P.A. | B27: CARACTERIZACIÓN DE FAUNA ÍCTICA ASOCIADA AL PROYECTO, PISCICULTURA SAN JOAQUÍN. RIO CISNES, HUALAIHUÉ ESTERO, COMUNA DE HUALAIHUÉ, PROVINCIA DE PALENA. REGIÓN DE LOS LAGOS. | C27: Juan Cárcamo Barría | D27: R. EX N°411-2017 | E27: Juan Cárcamo Barría (2017) Informe de resutados de pesca de investigación asociado al permiso SUBPESCA, R. EX N°411-2017. Proyecto: Caracterización de fauna íctica asociada al proyecto, piscicultura San Joaquín, sector El Varal, comuna de Hualaihué, X región de Los Lagos. Mandante: Cultivos Marinos Lago Yelcho S.P.A.
A28: GAMAN LIMNO STUDIES LTDA. | B28: CENTRAL HIDROELECTRICA CHAICA | C28: INGENIUM CIVIL S.A | D28: R.EX N°767/2014 | E28: Gaman Limno Studies Ltda. (2014) Informe de resutados de pesca de investigación asociado al permiso SUBPESCA, R.EX N°767/2014. Proyecto: Estudio Línea base de tipo limnológico del proyecto hidroeléctrico Chaica en el río Lenca, comuna de Puerto Montt, X Región. Mandante: Ingenium Civil S.A
A29: ICNOVA ING | B29: Proyecto de riego Magallanes, embalse río Porvenir | C29: Comisión Nacional de Riego | D29: R. EX N°838/2018 | E29: Icnova Ing (2018) Informe de resutados de pesca de investigación asociado al permiso SUBPESCA, R. EX N°838/2018. Proyecto: Caracterización limnológica asociado al proyecto de riego Magallanes, embalse río Porvenir, XII region de Magallanes y la Antártica Chilena. Mandante: Comisión Nacional de Riego.
A30: ICNOVA ING CONSULTORES | B30: Diagnostico Hidrobiológico de Laguna Escondida y Laguna Barrosa - Declaración de Impacto Ambiental Almacenamiento de Agua de Interior Mina Javiera en Laguna Salitrosa, Comuna de Chile Chico, XII Región de Aysén | C30: Compañía Minera Cerro Bayo Ltda | D30: R. EX N°388/2018 | E30: Icnova Ing Consultores (2018) Informe de resutados de pesca de investigación asociado al permiso SUBPESCA, R. EX N°388/2018. Proyecto: Diagnostico hidrobiológico de laguna Escondida y laguna Barrosa - declaración de impacto ambiental almacenamiento de agua de interior Mina Javiera en laguna Salitrosa, comuna de Chile Chico, XII Región de Aysén. Mandante: Compañía Minera Cerro Bayo Ltda.
A31: Jaime Illanes y Asociados Consultores S.A. | B31: Caracterización ecosistemas acuáticos continentales asociados al proyecto modificación piscicultura los Tilcos, Río Chico región de los Lagos | C31: Jaime Illanes y Asociados Consultores S.A. | D31: R. EX N°E-2021-074 | E31: Jaime Illanes y Asociados Consultores S.A. (2021) Informe de resutados de pesca de investigación asociado al permiso SUBPESCA, R. EX N°E-2021-074. Proyecto: Caracterización ecosistemas acuáticos continentales asociados al proyecto modificación Piscicultura los Tilcos, Río Chico Región de Los Lagos. Mandante: Piscicultura los Tilcos.
A32: Maring EIRL | B32: Piscultura El Arco | C32: Garo S.A | D32: R.EX N°262/2012 | E32: Maring Eirl (2012) Informe de resutados de pesca de investigación asociado al permiso SUBPESCA, R.EX N°262/2012. Proyecto: Evaluación limnológica-íctica, estero El Arco, Coyhaique, Región de Aysén. Mandante: Garo S.A.
A33: MARTINEZ AMBIENTAL LTDA | B33: MINA INVIERNO | C33: MINERA INVIERNO SA | D33: R.EX N°1628/2019 | E33: Martinez Ambiental Ltda (2019) Informe de resutados de pesca de investigación asociado al permiso SUBPESCA, R.EX N°1628/2019. Proyecto: Plan de vigilancia ambiental, asociado al proyecto Mina Invierno, comuna de Río Verde, región de Magallanes y Antártica Chilena. Mandante: Minera Invierno Sa.
A34: PHOTOSINTESIS | B34: CARACTERIZACIÓN LIMNOLÓGICA Y USO DE HÁBITATS RIBEREÑOS EN LOS LAGOS MEULLÍN, YULTON Y RÍO CUERVOS, REGIÓN DEL GRAL. CARLOS IBÁÑEZ DEL CAMPO | C34: Orcas SpA | D34: R. EX N°E-2021-117 | E34: Las Orcas Spa. (Photosintesis) (2021) Informe de resutados de pesca de investigación asociado al permiso SUBPESCA, R. EX N°E-2021-117. Proyecto: Caracterización limnológica y uso de hábitats ribereños en los lagos Meullín, Yulton y Río cuervos, región del General Carlos Ibáñez del Campo. Mandante: Fundación Kreen.
A38: Brian Reid | B38: 2022 | C38: Efecto de sedimentos suspendidos a la alimentación de los peces nativos e introducidos, en la cuenca del río Simpson, región de Aysén. | D38: Centro de Investigación de Ecosistemas de la Patagonia. | E38: R. EX N°E-2022-499 | F38: =CONCATENATE("Informe de resutados de pesca de investigación asociado al permiso SUBPESCA, ",E38,".") -> Informe de resutados de pesca de investigación asociado al permiso SUBPESCA, R. EX N°E-2022-499. | G38: =CONCATENATE(A38," (",B38,") ",F38," Proyecto: ",C38," Mandante: ",D38) -> Brian Reid (2022) Informe de resutados de pesca de investigación asociado al permiso SUBPESCA, R. EX N°E-2022-499. Proyecto: Efecto de sedimentos suspendidos a la alimentación de los peces nativos e introducidos, en la cuenca del río Simpson, región de Aysén. Mandante: Centro de Investigación de Ecosistemas de la Patagonia. | H38: Brian Reid (2022) Informe de resutados de pesca de investigación asociado al permiso SUBPESCA, R. EX N°E-2022-499. Proyecto: Efecto de sedimentos suspendidos a la alimentación de los peces nativos e introducidos, en la cuenca del río Simpson, región de Aysén. Centro de Investigación de Ecosistemas de la Patagonia.
A39: Claudia Verdugo Castro | B39: 2020 | C39: Línea base limnológica Río Trainel cercano a la Piscicultura Trainel, región de Los Lagos. | D39: Piscicultura Trainel | E39: R. EX. N° E-2020-607 | F39: =CONCATENATE("Informe de resutados de pesca de investigación asociado al permiso SUBPESCA, ",E39,".") -> Informe de resutados de pesca de investigación asociado al permiso SUBPESCA, R. EX. N° E-2020-607 . | G39: =CONCATENATE(A39," (",B39,") ",F39," Proyecto: ",C39," Mandante: ",D39) -> Claudia Verdugo Castro (2020) Informe de resutados de pesca de investigación asociado al permiso SUBPESCA, R. EX. N° E-2020-607 . Proyecto: Línea base limnológica Río Trainel cercano a la Piscicultura Trainel, región de Los Lagos. Mandante: Piscicultura Trainel | H39: Claudia Verdugo Castro (2020) Informe de resutados de pesca de investigación asociado al permiso SUBPESCA, R. EX. N° E-2020-607 . Proyecto: Línea base limnológica Río Trainel cercano a la Piscicultura Trainel, región de Los Lagos. Mandante: Piscicultura Trainel.
A40: Claudia Verdugo Castro | B40: 2020 | C40: Monitoreo limnológico proyecto refundición de RCA's Amplición y cambio operacional, río Petrohué, comuna de Puerto Varas, región de Los Lagos. | D40: Salmones Camanchaca S.A. | E40: R. EX N°65/2020 | F40: =CONCATENATE("Informe de resutados de pesca de investigación asociado al permiso SUBPESCA, ",E40,".") -> Informe de resutados de pesca de investigación asociado al permiso SUBPESCA, R. EX N°65/2020. | G40: =CONCATENATE(A40," (",B40,") ",F40," Proyecto: ",C40," Mandante: ",D40) -> Claudia Verdugo Castro (2020) Informe de resutados de pesca de investigación asociado al permiso SUBPESCA, R. EX N°65/2020. Proyecto: Monitoreo limnológico proyecto refundición de RCA's Amplición y cambio operacional, río Petrohué, comuna de Puerto Varas, región de Los Lagos. Mandante: Salmones Camanchaca S.A. | H40: Claudia Verdugo Castro (2020) Informe de resutados de pesca de investigación asociado al permiso SUBPESCA, R. EX N°65/2020. Proyecto: Monitoreo limnológico proyecto refundición de RCA's Amplición y cambio operacional, río Petrohué, comuna de Puerto Varas, región de Los Lagos. Mandante: Salmones Camanchaca S.A.
A41: Claudia Verdugo Castro (Ecosistema) | B41: 2016 | C41: Piscicultura de recirculación lago Balmaceda, Sealand Aquaculture S.A.; respuesta observación 1.2.8 ICSARA n°1 (064/2016). | D41: Sealand Aquaculture S.A. | E41: R.EX N°3232/2016 | F41: =CONCATENATE("Informe de resutados de pesca de investigación asociado al permiso SUBPESCA, ",E41,".") -> Informe de resutados de pesca de investigación asociado al permiso SUBPESCA, R.EX N°3232/2016. | G41: =CONCATENATE(A41," (",B41,") ",F41," Proyecto: ",C41," Mandante: ",D41) -> Claudia Verdugo Castro (Ecosistema) (2016) Informe de resutados de pesca de investigación asociado al permiso SUBPESCA, R.EX N°3232/2016. Proyecto: Piscicultura de recirculación lago Balmaceda, Sealand Aquaculture S.A.; respuesta observación 1.2.8 ICSARA n°1 (064/2016). Mandante: Sealand Aquaculture S.A. | H41: Claudia Verdugo Castro (Ecosistema) (2016) Informe de resutados de pesca de investigación asociado al permiso SUBPESCA, R.EX N°3232/2016. Proyecto: Piscicultura de recirculación lago Balmaceda, Sealand Aquaculture S.A.; respuesta observación 1.2.8 ICSARA n°1 (064/2016). Mandante: Sealand Aquaculture S.A.
A42: Juan Cárcamo Barría | B42: 2017 | C42: Caracterización de fauna íctica asociada al proyecto, piscicultura San Joaquín, sector El Varal, comuna de Hualaihué, X región de Los Lagos. | D42: Cultivos Marinos Lago Yelcho S.P.A. | E42: R. EX N°411-2017 | F42: =CONCATENATE("Informe de resutados de pesca de investigación asociado al permiso SUBPESCA, ",E42,".") -> Informe de resutados de pesca de investigación asociado al permiso SUBPESCA, R. EX N°411-2017. | G42: =CONCATENATE(A42," (",B42,") ",F42," Proyecto: ",C42," Mandante: ",D42) -> Juan Cárcamo Barría (2017) Informe de resutados de pesca de investigación asociado al permiso SUBPESCA, R. EX N°411-2017. Proyecto: Caracterización de fauna íctica asociada al proyecto, piscicultura San Joaquín, sector El Varal, comuna de Hualaihué, X región de Los Lagos. Mandante: Cultivos Marinos Lago Yelcho S.P.A. | H42: Juan Cárcamo Barría (2017) Informe de resutados de pesca de investigación asociado al permiso SUBPESCA, R. EX N°411-2017. Proyecto: Caracterización de fauna íctica asociada al proyecto, piscicultura San Joaquín, sector El Varal, comuna de Hualaihué, X región de Los Lagos. Mandante: Cultivos Marinos Lago Yelcho S.P.A.
A43: Gaman Limno Studies Ltda. | B43: 2014 | C43: Estudio Línea base de tipo limnológico del proyecto hidroeléctrico Chaica en el río Lenca, comuna de Puerto Montt, X Región. | D43: Ingenium Civil S.A | E43: R.EX N°767/2014 | F43: =CONCATENATE("Informe de resutados de pesca de investigación asociado al permiso SUBPESCA, ",E43,".") -> Informe de resutados de pesca de investigación asociado al permiso SUBPESCA, R.EX N°767/2014. | G43: =CONCATENATE(A43," (",B43,") ",F43," Proyecto: ",C43," Mandante: ",D43) -> Gaman Limno Studies Ltda. (2014) Informe de resutados de pesca de investigación asociado al permiso SUBPESCA, R.EX N°767/2014. Proyecto: Estudio Línea base de tipo limnológico del proyecto hidroeléctrico Chaica en el río Lenca, comuna de Puerto Montt, X Región. Mandante: Ingenium Civil S.A | H43: Gaman Limno Studies Ltda. (2014) Informe de resutados de pesca de investigación asociado al permiso SUBPESCA, R.EX N°767/2014. Proyecto: Estudio Línea base de tipo limnológico del proyecto hidroeléctrico Chaica en el río Lenca, comuna de Puerto Montt, X Región. Mandante: Ingenium Civil S.A
A44: Icnova Ing | B44: 2018 | C44: Caracterización limnológica asociado al proyecto de riego Magallanes, embalse río Porvenir, XII region de Magallanes y la Antártica Chilena. | D44: Comisión Nacional de Riego | E44: R. EX N°838/2018 | F44: =CONCATENATE("Informe de resutados de pesca de investigación asociado al permiso SUBPESCA, ",E44,".") -> Informe de resutados de pesca de investigación asociado al permiso SUBPESCA, R. EX N°838/2018. | G44: =CONCATENATE(A44," (",B44,") ",F44," Proyecto: ",C44," Mandante: ",D44) -> Icnova Ing (2018) Informe de resutados de pesca de investigación asociado al permiso SUBPESCA, R. EX N°838/2018. Proyecto: Caracterización limnológica asociado al proyecto de riego Magallanes, embalse río Porvenir, XII region de Magallanes y la Antártica Chilena. Mandante: Comisión Nacional de Riego | H44: Icnova Ing (2018) Informe de resutados de pesca de investigación asociado al permiso SUBPESCA, R. EX N°838/2018. Proyecto: Caracterización limnológica asociado al proyecto de riego Magallanes, embalse río Porvenir, XII region de Magallanes y la Antártica Chilena. Mandante: Comisión Nacional de Riego.
A45: Icnova Ing Consultores | B45: 2018 | C45: Diagnostico hidrobiológico de laguna Escondida y laguna Barrosa - declaración de impacto ambiental almacenamiento de agua de interior Mina Javiera en laguna Salitrosa, comuna de Chile Chico, XII Región de Aysén. | D45: Compañía Minera Cerro Bayo Ltda. | E45: R. EX N°388/2018 | F45: =CONCATENATE("Informe de resutados de pesca de investigación asociado al permiso SUBPESCA, ",E45,".") -> Informe de resutados de pesca de investigación asociado al permiso SUBPESCA, R. EX N°388/2018. | G45: =CONCATENATE(A45," (",B45,") ",F45," Proyecto: ",C45," Mandante: ",D45) -> Icnova Ing Consultores (2018) Informe de resutados de pesca de investigación asociado al permiso SUBPESCA, R. EX N°388/2018. Proyecto: Diagnostico hidrobiológico de laguna Escondida y laguna Barrosa - declaración de impacto ambiental almacenamiento de agua de interior Mina Javiera en laguna Salitrosa, comuna de Chile Chico, XII Región de Aysén. Mandante: Compañía Minera Cerro Bayo Ltda. | H45: Icnova Ing Consultores (2018) Informe de resutados de pesca de investigación asociado al permiso SUBPESCA, R. EX N°388/2018. Proyecto: Diagnostico hidrobiológico de laguna Escondida y laguna Barrosa - declaración de impacto ambiental almacenamiento de agua de interior Mina Javiera en laguna Salitrosa, comuna de Chile Chico, XII Región de Aysén. Mandante: Compañía Minera Cerro Bayo Ltda.
A46: Jaime Illanes y Asociados Consultores S.A. | B46: 2021 | C46: Caracterización ecosistemas acuáticos continentales asociados al proyecto modificación Piscicultura los Tilcos, Río Chico Región de Los Lagos. | D46: Piscicultura los Tilcos | E46: R. EX N°E-2021-074 | F46: =CONCATENATE("Informe de resutados de pesca de investigación asociado al permiso SUBPESCA, ",E46,".") -> Informe de resutados de pesca de investigación asociado al permiso SUBPESCA, R. EX N°E-2021-074. | G46: =CONCATENATE(A46," (",B46,") ",F46," Proyecto: ",C46," Mandante: ",D46) -> Jaime Illanes y Asociados Consultores S.A. (2021) Informe de resutados de pesca de investigación asociado al permiso SUBPESCA, R. EX N°E-2021-074. Proyecto: Caracterización ecosistemas acuáticos continentales asociados al proyecto modificación Piscicultura los Tilcos, Río Chico Región de Los Lagos. Mandante: Piscicultura los Tilcos | H46: Jaime Illanes y Asociados Consultores S.A. (2021) Informe de resutados de pesca de investigación asociado al permiso SUBPESCA, R. EX N°E-2021-074. Proyecto: Caracterización ecosistemas acuáticos continentales asociados al proyecto modificación Piscicultura los Tilcos, Río Chico Región de Los Lagos. Mandante: Piscicultura los Tilcos.
A47: Maring Eirl | B47: 2012 | C47: Evaluación limnológica-íctica, estero El Arco, Coyhaique, Región de Aysén. | D47: Garo S.A | E47: R.EX N°262/2012 | F47: =CONCATENATE("Informe de resutados de pesca de investigación asociado al permiso SUBPESCA, ",E47,".") -> Informe de resutados de pesca de investigación asociado al permiso SUBPESCA, R.EX N°262/2012. | G47: =CONCATENATE(A47," (",B47,") ",F47," Proyecto: ",C47," Mandante: ",D47) -> Maring Eirl (2012) Informe de resutados de pesca de investigación asociado al permiso SUBPESCA, R.EX N°262/2012. Proyecto: Evaluación limnológica-íctica, estero El Arco, Coyhaique, Región de Aysén. Mandante: Garo S.A | H47: Maring Eirl (2012) Informe de resutados de pesca de investigación asociado al permiso SUBPESCA, R.EX N°262/2012. Proyecto: Evaluación limnológica-íctica, estero El Arco, Coyhaique, Región de Aysén. Mandante: Garo S.A.
A48: Martinez Ambiental Ltda | B48: 2019 | C48: Plan de vigilancia ambiental, asociado al proyecto Mina Invierno, comuna de Río Verde, región de Magallanes y Antártica Chilena. | D48: Minera Invierno Sa | E48: R.EX N°1628/2019 | F48: =CONCATENATE("Informe de resutados de pesca de investigación asociado al permiso SUBPESCA, ",E48,".") -> Informe de resutados de pesca de investigación asociado al permiso SUBPESCA, R.EX N°1628/2019. | G48: =CONCATENATE(A48," (",B48,") ",F48," Proyecto: ",C48," Mandante: ",D48) -> Martinez Ambiental Ltda (2019) Informe de resutados de pesca de investigación asociado al permiso SUBPESCA, R.EX N°1628/2019. Proyecto: Plan de vigilancia ambiental, asociado al proyecto Mina Invierno, comuna de Río Verde, región de Magallanes y Antártica Chilena. Mandante: Minera Invierno Sa | H48: Martinez Ambiental Ltda (2019) Informe de resutados de pesca de investigación asociado al permiso SUBPESCA, R.EX N°1628/2019. Proyecto: Plan de vigilancia ambiental, asociado al proyecto Mina Invierno, comuna de Río Verde, región de Magallanes y Antártica Chilena. Mandante: Minera Invierno Sa.
A49: Las Orcas Spa. (Photosintesis) | B49: 2021 | C49: Caracterización limnológica y uso de hábitats ribereños en los lagos Meullín, Yulton y Río cuervos, región del General Carlos Ibáñez del Campo. | D49: Fundación Kreen | E49: R. EX N°E-2021-117 | F49: =CONCATENATE("Informe de resutados de pesca de investigación asociado al permiso SUBPESCA, ",E49,".") -> Informe de resutados de pesca de investigación asociado al permiso SUBPESCA, R. EX N°E-2021-117. | G49: =CONCATENATE(A49," (",B49,") ",F49," Proyecto: ",C49," Mandante: ",D49) -> Las Orcas Spa. (Photosintesis) (2021) Informe de resutados de pesca de investigación asociado al permiso SUBPESCA, R. EX N°E-2021-117. Proyecto: Caracterización limnológica y uso de hábitats ribereños en los lagos Meullín, Yulton y Río cuervos, región del General Carlos Ibáñez del Campo. Mandante: Fundación Kreen | H49: Las Orcas Spa. (Photosintesis) (2021) Informe de resutados de pesca de investigación asociado al permiso SUBPESCA, R. EX N°E-2021-117. Proyecto: Caracterización limnológica y uso de hábitats ribereños en los lagos Meullín, Yulton y Río cuervos, región del General Carlos Ibáñez del Campo. Mandante: Fundación Kreen.
B50: =LOWER( B35 ) | C50: =PROPER(C35)
...

Sheet Original
A1: N° DE RESOLUCIÓN SUBPESCA | B1: EJECUTOR | C1: TITULO PROYECTO | D1: MANDANTE O TITULAR | F1: FUENTE | G1: CUENCA | H1: MES | I1: AÑO | J1: HORA DE MUESTREO | K1: ESTACIÓN | L1: LATITUD | M1: LONGITUD | N1: GRUPO TAXONÓMICO | O1: NOMBRE CIENTÍFICO | P1: NOMBRE COMÚN | Q1: N° INDIVIDUOS | R1: TIPO DE ARTE | S1: VALOR CPUE | T1: UNIDAD CPUE | U1: Nº SACRIFICADOS | V1: DIDYMO VISUAL | W1: MUESTRA | X1: NOMBRE CIENTÍFICO | Y1: NOMBRE COMÚN | Z1: N° DE INDIVIDUOS | AA1: PESO_MIN_GR | AB1: PESO_MAX_GR | AC1: PESO_PROMEDIO | AD1: PESO D.S. | AE1: N° DE INDIVIDUOS | AF1: LONG_MIN_CM | AG1: LONG_MAX_CM | AH1: LONG_PROMEDIO | AI1: LONG_D.S.
A2: R.EX N°262/2012 | B2: Maring EIRL | C2: Piscultura El Arco | D2: Garo S.A | E2: =INDEX(Sheet1!$E$23:$E$34,MATCH(A2,Sheet1!$D$23:$D$34,0)) -> Maring Eirl (2012) Informe de resutados de pesca de investigación asociado al permiso SUBPESCA, R.EX N°262/2012. Proyecto: Evaluación limnológica-íctica, estero El Arco, Coyhaique, Región de Aysén. Mandante: Garo S.A. | F2: PRIVADA | G2: Río Simpson | H2: FEBRERO | I2: 2012 | J2: 0.41666667 | K2: 1 | L2: -45.746925 | M2: -72.122614 | N2: PECES | O2: Oncorhynchus mykiss | P2: Trucha Arcoíris | Q2: 1 | R2: 1. PESCA ELÉCTRICA | S2: 1 | T2: (IND/HORA) | U2: 0 | V2: NO | W2: SI | X2: Oncorhynchus mykiss | Y2: Trucha Arcoíris | Z2: 1 | AA2: 5 | AB2: 5 | AC2: 5 | AD2: 0 | AE2: 1 | AF2: 5.2 | AG2: 5.2 | AH2: 5.2 | AI2: 0
A3: R.EX N°262/2012 | B3: Maring EIRL | C3: Piscultura El Arco | D3: Garo S.A | E3: =INDEX(Sheet1!$E$23:$E$34,MATCH(A3,Sheet1!$D$23:$D$34,0)) -> Maring Eirl (2012) Informe de resutados de pesca de investigación asociado al permiso SUBPESCA, R.EX N°262/2012. Proyecto: Evaluación limnológica-íctica, estero El Arco, Coyhaique, Región de Aysén. Mandante: Garo S.A. | F3: PRIVADA | G3: Río Simpson | H3: FEBRERO | I3: 2012 | J3: 0.45833333 | K3: 1 | L3: -45.746925 | M3: -72.122614 | N3: PECES | O3: Salmo trutta | P3: TRUCHA CAFÉ | Q3: 28 | R3: 1. PESCA ELÉCTRICA | S3: 28 | T3: (IND/HORA) | U3: 0 | V3: NO | W3: SI | X3: Salmo trutta | Y3: TRUCHA CAFÉ | Z3: 28 | AA3: 0.7 | AB3: 140 | AC3: 13.207143 | AD3: 31.432796 | AE3: 28 | AF3: 4.2 | AG3: 19.8 | AH3: 7.9 | AI3: 3.8707832
A4: R.EX N°262/2012 | B4: Maring EIRL | C4: Piscultura El Arco | D4: Garo S.A | E4: =INDEX(Sheet1!$E$23:$E$34,MATCH(A4,Sheet1!$D$23:$D$34,0)) -> Maring Eirl (2012) Informe de resutados de pesca de investigación asociado al permiso SUBPESCA, R.EX N°262/2012. Proyecto: Evaluación limnológica-íctica, estero El Arco, Coyhaique, Región de Aysén. Mandante: Garo S.A. | F4: PRIVADA | G4: Río Simpson | H4: FEBRERO | I4: 2012 | J4: 0.5 | K4: 2 | L4: -45.747222 | M4: -72.132889 | N4: PECES | O4: Salmo trutta | P4: TRUCHA CAFÉ | Q4: 32 | R4: 1. PESCA ELÉCTRICA | S4: 32 | T4: (IND/HORA) | U4: 0 | V4: NO | W4: SI | X4: Salmo trutta | Y4: TRUCHA CAFÉ | Z4: 32 | AA4: 0.8 | AB4: 1200 | AC4: 58.53125 | AD4: 222.25218 | AE4: 32 | AF4: 4.1 | AG4: 48.5 | AH4: 8.834375 | AI4: 9.5790635
A5: R.EX N°262/2012 | B5: Maring EIRL | C5: Piscultura El Arco | D5: Garo S.A | E5: =INDEX(Sheet1!$E$23:$E$34,MATCH(A5,Sheet1!$D$23:$D$34,0)) -> Maring Eirl (2012) Informe de resutados de pesca de investigación asociado al permiso SUBPESCA, R.EX N°262/2012. Proyecto: Evaluación limnológica-íctica, estero El Arco, Coyhaique, Región de Aysén. Mandante: Garo S.A. | F5: PRIVADA | G5: Río Simpson | H5: FEBRERO | I5: 2012 | J5: 0.54166667 | K5: 3 | L5: -45.743194 | M5: -72.143 | N5: PECES | O5: Oncorhynchus mykiss | P5: Trucha Arcoíris | Q5: 2 | R5: 1. PESCA ELÉCTRICA | S5: 2 | T5: (IND/HORA) | U5: 0 | V5: NO | W5: SI | X5: Oncorhynchus mykiss | Y5: Trucha Arcoíris | Z5: 2 | AA5: 5 | AB5: 5 | AC5: 5 | AD5: 0 | AE5: 2 | AF5: 5.2 | AG5: 5.6 | AH5: 5.4 | AI5: 0.28284271
A6: R.EX N°262/2012 | B6: Maring EIRL | C6: Piscultura El Arco | D6: Garo S.A | E6: =INDEX(Sheet1!$E$23:$E$34,MATCH(A6,Sheet1!$D$23:$D$34,0)) -> Maring Eirl (2012) Informe de resutados de pesca de investigación asociado al permiso SUBPESCA, R.EX N°262/2012. Proyecto: Evaluación limnológica-íctica, estero El Arco, Coyhaique, Región de Aysén. Mandante: Garo S.A. | F6: PRIVADA | G6: Río Simpson | H6: FEBRERO | I6: 2012 | J6: 0.58333333 | K6: 3 | L6: -45.743194 | M6: -72.143 | N6: PECES | O6: Salmo trutta | P6: TRUCHA CAFÉ | Q6: 16 | R6: 1. PESCA ELÉCTRICA | S6: 16 | T6: (IND/HORA) | U6: 0 | V6: NO | W6: SI | X6: Salmo trutta | Y6: TRUCHA CAFÉ | Z6: 16 | AA6: 5 | AB6: 45 | AC6: 16 | AD6: 16.309506 | AE6: 16 | AF6: 5.8 | AG6: 16.4 | AH6: 10.775 | AI6: 4.0182086
A7: R.EX N°767/2014 | B7: GAMAN LIMNO STUDIES LTDA. | C7: CENTRAL HIDROELECTRICA CHAICA | D7: INGENIUM CIVIL S.A | E7: =INDEX(Sheet1!$E$23:$E$34,MATCH(A7,Sheet1!$D$23:$D$34,0)) -> Gaman Limno Studies Ltda. (2014) Informe de resutados de pesca de investigación asociado al permiso SUBPESCA, R.EX N°767/2014. Proyecto: Estudio Línea base de tipo limnológico del proyecto hidroeléctrico Chaica en el río Lenca, comuna de Puerto Montt, X Región. Mandante: Ingenium Civil S.A | F7: PRIVADA | G7: CHAICA | H7: MARZO | I7: 2014 | J7: 0.29166667 | K7: E1 | L7: 41°35'52.80"S | M7: 72°36'2.00"O | N7: Actinopterygii | O7: Salmo salar | P7: Salmón del Atlántico | Q7: 2 | R7: 2. ESPINEL | S7: 0.017 | T7: (IND/N°ANZ/HORA) | U7: 0 | V7: NO | W7: NO | X7: Salmo salar | Y7: Salmón del Atlántico | Z7: 2 | AA7: 45.2 | AB7: 82.1 | AC7: 63.7 | AD7: 26.09 | AE7: 2 | AF7: 17.5 | AG7: 19.5 | AH7: 18.5 | AI7: 1.41
A8: R.EX N°767/2014 | B8: GAMAN LIMNO STUDIES LTDA. | C8: CENTRAL HIDROELECTRICA CHAICA | D8: INGENIUM CIVIL S.A | E8: =INDEX(Sheet1!$E$23:$E$34,MATCH(A8,Sheet1!$D$23:$D$34,0)) -> Gaman Limno Studies Ltda. (2014) Informe de resutados de pesca de investigación asociado al permiso SUBPESCA, R.EX N°767/2014. Proyecto: Estudio Línea base de tipo limnológico del proyecto hidroeléctrico Chaica en el río Lenca, comuna de Puerto Montt, X Región. Mandante: Ingenium Civil S.A | F8: PRIVADA | G8: CHAICA | H8: MARZO | I8: 2014 | J8: 0.29166667 | K8: E1 | L8: 41°35'52.80"S | M8: 72°36'2.00"O | N8: Actinopterygii | O8: Salmo trutta | P8: Trucha café | Q8: 1 | R8: 2. ESPINEL | S8: 0.08 | T8: (IND/N°ANZ/HORA) | U8: 0 | V8: NO | W8: NO | X8: Salmo trutta | Y8: Trucha café | Z8: 1 | AA8: 25.5 | AB8: 25.5 | AC8: 25.5 | AD8: - | AE8: 1 | AF8: 13.6 | AG8: 13.6 | AH8: 13.6 | AI8: -
A9: R.EX N°767/2014 | B9: GAMAN LIMNO STUDIES LTDA. | C9: CENTRAL HIDROELECTRICA CHAICA | D9: INGENIUM CIVIL S.A | E9: =INDEX(Sheet1!$E$23:$E$34,MATCH(A9,Sheet1!$D$23:$D$34,0)) -> Gaman Limno Studies Ltda. (2014) Informe de resutados de pesca de investigación asociado al permiso SUBPESCA, R.EX N°767/2014. Proyecto: Estudio Línea base de tipo limnológico del proyecto hidroeléctrico Chaica en el río Lenca, comuna de Puerto Montt, X Región. Mandante: Ingenium Civil S.A | F9: PRIVADA | G9: CHAICA | H9: MARZO | I9: 2014 | J9: 0.375 | K9: E2 | L9: 41°36'8.55"S | M9: 72°36'59.17"O | N9: Actinopterygii | O9: Salmo salar | P9: Salmón del Atlántico | Q9: 1 | R9: 1. PESCA ELÉCTRICA | S9: 1 | T9: (IND/HORA) | U9: 0 | V9: NO | W9: NO | X9: Salmo salar | Y9: Salmón del Atlántico | Z9: 1 | AA9: 2.2 | AB9: 2.2 | AC9: 2.2 | AD9: - | AE9: 1 | AF9: 5.7 | AG9: 5.7 | AH9: 5.7 | AI9: -
A10: R.EX N°767/2014 | B10: GAMAN LIMNO STUDIES LTDA. | C10: CENTRAL HIDROELECTRICA CHAICA | D10: INGENIUM CIVIL S.A | E10: =INDEX(Sheet1!$E$23:$E$34,MATCH(A10,Sheet1!$D$23:$D$34,0)) -> Gaman Limno Studies Ltda. (2014) Informe de resutados de pesca de investigación asociado al permiso SUBPESCA, R.EX N°767/2014. Proyecto: Estudio Línea base de tipo limnológico del proyecto hidroeléctrico Chaica en el río Lenca, comuna de Puerto Montt, X Región. Mandante: Ingenium Civil S.A | F10: PRIVADA | G10: CHAICA | H10: MARZO | I10: 2014 | J10: 0.75 | K10: E3 | L10: 41°36'22.59"S | M10: 72°38'43.20"O | N10: Actinopterygii | O10: Salmo salar | P10: Salmón del Atlántico | Q10: 1 | R10: 1. PESCA ELÉCTRICA | S10: 1 | T10: (IND/HORA) | U10: 0 | V10: NO | W10: NO | X10: Salmo salar | Y10: Salmón del Atlántico | Z10: 1 | AA10: 990 | AB10: 990 | AC10: 990 | AD10: - | AE10: 1 | AF10: 49.5 | AG10: 49.5 | AH10: 49.5 | AI10: -
A11: R.EX N°767/2014 | B11: GAMAN LIMNO STUDIES LTDA. | C11: CENTRAL HIDROELECTRICA CHAICA | D11: INGENIUM CIVIL S.A | E11: =INDEX(Sheet1!$E$23:$E$34,MATCH(A11,Sheet1!$D$23:$D$34,0)) -> Gaman Limno Studies Ltda. (2014) Informe de resutados de pesca de investigación asociado al permiso SUBPESCA, R.EX N°767/2014. Proyecto: Estudio Línea base de tipo limnológico del proyecto hidroeléctrico Chaica en el río Lenca, comuna de Puerto Montt, X Región. Mandante: Ingenium Civil S.A | F11: PRIVADA | G11: CHAICA | H11: MARZO | I11: 2014 | J11: 0.75 | K11: E3 | L11: 41°36'22.59"S | M11: 72°38'43.20"O | N11: Actinopterygii | O11: Salmo salar | P11: Salmón del Atlántico | Q11: 1 | R11: 2. ESPINEL | S11: 0.008 | T11: (IND/N°ANZ/HORA) | U11: 0 | V11: NO | W11: NO | X11: Salmo salar | Y11: Salmón del Atlántico | Z11: 1 | AA11: 80.7 | AB11: 80.7 | AC11: 80.7 | AD11: - | AE11: 1 | AF11: 17.2 | AG11: 17.2 | AH11: 17.2 | AI11: -
A12: R.EX N°767/2014 | B12: GAMAN LIMNO STUDIES LTDA. | C12: CENTRAL HIDROELECTRICA CHAICA | D12: INGENIUM CIVIL S.A | E12: =INDEX(Sheet1!$E$23:$E$34,MATCH(A12,Sheet1!$D$23:$D$34,0)) -> Gaman Limno Studies Ltda. (2014) Informe de resutados de pesca de investigación asociado al permiso SUBPESCA, R.EX N°767/2014. Proyecto: Estudio Línea base de tipo limnológico del proyecto hidroeléctrico Chaica en el río Lenca, comuna de Puerto Montt, X Región. Mandante: Ingenium Civil S.A | F12: PRIVADA | G12: CHAICA | H12: MARZO | I12: 2014 | J12: 0.75 | K12: E3 | L12: 41°36'22.59"S | M12: 72°38'43.20"O | N12: Actinopterygii | O12: Salmo trutta | P12: Trucha café | Q12: 3 | R12: 2. ESPINEL | S12: 0.25 | T12: (IND/N°ANZ/HORA) | U12: 0 | V12: NO | W12: NO | X12: Salmo trutta | Y12: Trucha café | Z12: 3 | AA12: 39.3 | AB12: 240.7 | AC12: 158.4 | AD12: 105.61 | AE12: 3 | AF12: 14.9 | AG12: 28 | AH12: 23.1 | AI12: 7.17
A13: R.EX N°767/2014 | B13: GAMAN LIMNO STUDIES LTDA. | C13: CENTRAL HIDROELECTRICA CHAICA | D13: INGENIUM CIVIL S.A | E13: =INDEX(Sheet1!$E$23:$E$34,MATCH(A13,Sheet1!$D$23:$D$34,0)) -> Gaman Limno Studies Ltda. (2014) Informe de resutados de pesca de investigación asociado al permiso SUBPESCA, R.EX N°767/2014. Proyecto: Estudio Línea base de tipo limnológico del proyecto hidroeléctrico Chaica en el río Lenca, comuna de Puerto Montt, X Región. Mandante: Ingenium Civil S.A | F13: PRIVADA | G13: CHAICA | H13: MARZO | I13: 2014 | J13: 0.33333333 | K13: E4 | L13: 41°36'29.23"S | M13: 72°39'9.66"O | N13: Actinopterygii | O13: Salmo trutta | P13: Trucha café | Q13: 1 | R13: 1. PESCA ELÉCTRICA | S13: 1 | T13: (IND/HORA) | U13: 0 | V13: NO | W13: NO | X13: Salmo trutta | Y13: Trucha café | Z13: 1 | AA13: 2.4 | AB13: 2.4 | AC13: 2.4 | AD13: - | AE13: 1 | AF13: 5.7 | AG13: 5.7 | AH13: 5.7 | AI13: -
A14: R.EX N°767/2014 | B14: GAMAN LIMNO STUDIES LTDA. | C14: CENTRAL HIDROELECTRICA CHAICA | D14: INGENIUM CIVIL S.A | E14: =INDEX(Sheet1!$E$23:$E$34,MATCH(A14,Sheet1!$D$23:$D$34,0)) -> Gaman Limno Studies Ltda. (2014) Informe de resutados de pesca de investigación asociado al permiso SUBPESCA, R.EX N°767/2014. Proyecto: Estudio Línea base de tipo limnológico del proyecto hidroeléctrico Chaica en el río Lenca, comuna de Puerto Montt, X Región. Mandante: Ingenium Civil S.A | F14: PRIVADA | G14: CHAICA | H14: MARZO | I14: 2014 | J14: 0.41666667 | K14: E5 | L14: 41°36'38.76"S | M14: 72°39'14.32"O | N14: Actinopterygii | O14: Salmo salar | P14: Salmón del Atlántico | Q14: 1 | R14: 1. PESCA ELÉCTRICA | S14: 1 | T14: (IND/HORA) | U14: 0 | V14: NO | W14: NO | X14: Salmo salar | Y14: Salmón del Atlántico | Z14: 1 | AA14: 39.9 | AB14: 39.9 | AC14: 39.9 | AD14: - | AE14: 1 | AF14: 14.9 | AG14: 14.9 | AH14: 14.9 | AI14: -
A15: R.EX N°767/2014 | B15: GAMAN LIMNO STUDIES LTDA. | C15: CENTRAL HIDROELECTRICA CHAICA | D15: INGENIUM CIVIL S.A | E15: =INDEX(Sheet1!$E$23:$E$34,MATCH(A15,Sheet1!$D$23:$D$34,0)) -> Gaman Limno Studies Ltda. (2014) Informe de resutados de pesca de investigación asociado al permiso SUBPESCA, R.EX N°767/2014. Proyecto: Estudio Línea base de tipo limnológico del proyecto hidroeléctrico Chaica en el río Lenca, comuna de Puerto Montt, X Región. Mandante: Ingenium Civil S.A | F15: PRIVADA | G15: CHAICA | H15: MARZO | I15: 2014 | J15: 0.41666667 | K15: E5 | L15: 41°36'38.76"S | M15: 72°39'14.32"O | N15: Actinopterygii | O15: Aplochiton zebra | P15: Peladilla | Q15: 1 | R15: 1. PESCA ELÉCTRICA | S15: 1 | T15: (IND/HORA) | U15: 0 | V15: NO | W15: NO | X15: Aplochiton zebra | Y15: Peladilla | Z15: 1 | AA15: 9.4 | AB15: 9.4 | AC15: 9.4 | AD15: - | AE15: 1 | AF15: 8.6 | AG15: 8.6 | AH15: 8.6 | AI15: -
A16: R.EX N°767/2014 | B16: GAMAN LIMNO STUDIES LTDA. | C16: CENTRAL HIDROELECTRICA CHAICA | D16: INGENIUM CIVIL S.A | E16: =INDEX(Sheet1!$E$23:$E$34,MATCH(A16,Sheet1!$D$23:$D$34,0)) -> Gaman Limno Studies Ltda. (2014) Informe de resutados de pesca de investigación asociado al permiso SUBPESCA, R.EX N°767/2014. Proyecto: Estudio Línea base de tipo limnológico del proyecto hidroeléctrico Chaica en el río Lenca, comuna de Puerto Montt, X Región. Mandante: Ingenium Civil S.A | F16: PRIVADA | G16: CHAICA | H16: MARZO | I16: 2014 | J16: 0.41666667 | K16: E5 | L16: 41°36'38.76"S | M16: 72°39'14.32"O | N16: Actinopterygii | O16: Galaxias maculatus | P16: Puye | Q16: 6 | R16: 1. PESCA ELÉCTRICA | S16: 6 | T16: (IND/HORA) | U16: 0 | V16: NO | W16: NO | X16: Galaxias maculatus | Y16: Puye | Z16: 6 | AA16: 1.3 | AB16: 2.3 | AC16: 1.7 | AD16: 0.37 | AE16: 6 | AF16: 6.4 | AG16: 6.9 | AH16: 6.6 | AI16: 0.4
A17: R.EX N°767/2014 | B17: GAMAN LIMNO STUDIES LTDA. | C17: CENTRAL HIDROELECTRICA CHAICA | D17: INGENIUM CIVIL S.A | E17: =INDEX(Sheet1!$E$23:$E$34,MATCH(A17,Sheet1!$D$23:$D$34,0)) -> Gaman Limno Studies Ltda. (2014) Informe de resutados de pesca de investigación asociado al permiso SUBPESCA, R.EX N°767/2014. Proyecto: Estudio Línea base de tipo limnológico del proyecto hidroeléctrico Chaica en el río Lenca, comuna de Puerto Montt, X Región. Mandante: Ingenium Civil S.A | F17: PRIVADA | G17: CHAICA | H17: JULIO | I17: 2014 | J17: 0.375 | K17: E1 | L17: 41°35'52.80"S | M17: 72°36'2.00"O | N17: Actinopterygii | O17: Salmo trutta | P17: Trucha café | Q17: 1 | R17: 2. ESPINEL | S17: 0.008 | T17: (IND/N°ANZ/HORA) | U17: 0 | V17: NO | W17: NO | X17: Salmo trutta | Y17: Trucha café | Z17: 1 | AA17: 690 | AB17: 690 | AC17: 690 | AD17: - | AE17: 1 | AF17: 39 | AG17: 39 | AH17: 39 | AI17: -
A18: R.EX N°767/2014 | B18: GAMAN LIMNO STUDIES LTDA. | C18: CENTRAL HIDROELECTRICA CHAICA | D18: INGENIUM CIVIL S.A | E18: =INDEX(Sheet1!$E$23:$E$34,MATCH(A18,Sheet1!$D$23:$D$34,0)) -> Gaman Limno Studies Ltda. (2014) Informe de resutados de pesca de investigación asociado al permiso SUBPESCA, R.EX N°767/2014. Proyecto: Estudio Línea base de tipo limnológico del proyecto hidroeléctrico Chaica en el río Lenca, comuna de Puerto Montt, X Región. Mandante: Ingenium Civil S.A | F18: PRIVADA | G18: CHAICA | H18: JULIO | I18: 2014 | J18: 0.4375 | K18: E2 | L18: 41°36'8.55"S | M18: 72°36'59.17"O | N18: Actinopterygii | O18: Salmo trutta | P18: Trucha café | Q18: 1 | R18: 1. PESCA ELÉCTRICA | S18: 1 | T18: (IND/HORA) | U18: 0 | V18: NO | W18: NO | X18: Salmo trutta | Y18: Trucha café | Z18: 1 | AA18: 20 | AB18: 20 | AC18: 20 | AD18: - | AE18: 1 | AF18: 11.5 | AG18: 11.5 | AH18: 11.5 | AI18: -
A19: R.EX N°767/2014 | B19: GAMAN LIMNO STUDIES LTDA. | C19: CENTRAL HIDROELECTRICA CHAICA | D19: INGENIUM CIVIL S.A | E19: =INDEX(Sheet1!$E$23:$E$34,MATCH(A19,Sheet1!$D$23:$D$34,0)) -> Gaman Limno Studies Ltda. (2014) Informe de resutados de pesca de investigación asociado al permiso SUBPESCA, R.EX N°767/2014. Proyecto: Estudio Línea base de tipo limnológico del proyecto hidroeléctrico Chaica en el río Lenca, comuna de Puerto Montt, X Región. Mandante: Ingenium Civil S.A | F19: PRIVADA | G19: CHAICA | H19: JULIO | I19: 2014 | J19: 0.70833333 | K19: E3 | L19: 41°36'22.59"S | M19: 72°38'43.20"O | N19: Actinopterygii | O19: Salmo salar | P19: Salmón del Atlántico | Q19: 1 | R19: 1. PESCA ELÉCTRICA | S19: 1 | T19: (IND/HORA) | U19: 0 | V19: NO | W19: NO | X19: Salmo salar | Y19: Salmón del Atlántico | Z19: 1 | AA19: 2.2 | AB19: 2.2 | AC19: 2.2 | AD19: - | AE19: 1 | AF19: 5.6 | AG19: 5.6 | AH19: 5.6 | AI19: -
A20: R.EX N°767/2014 | B20: GAMAN LIMNO STUDIES LTDA. | C20: CENTRAL HIDROELECTRICA CHAICA | D20: INGENIUM CIVIL S.A | E20: =INDEX(Sheet1!$E$23:$E$34,MATCH(A20,Sheet1!$D$23:$D$34,0)) -> Gaman Limno Studies Ltda. (2014) Informe de resutados de pesca de investigación asociado al permiso SUBPESCA, R.EX N°767/2014. Proyecto: Estudio Línea base de tipo limnológico del proyecto hidroeléctrico Chaica en el río Lenca, comuna de Puerto Montt, X Región. Mandante: Ingenium Civil S.A | F20: PRIVADA | G20: CHAICA | H20: JULIO | I20: 2014 | J20: 0.70833333 | K20: E3 | L20: 41°36'22.59"S | M20: 72°38'43.20"O | N20: Actinopterygii | O20: Salmo trutta | P20: Trucha café | Q20: 2 | R20: 1. PESCA ELÉCTRICA | S20: 2 | T20: (IND/HORA) | U20: 0 | V20: NO | W20: NO | X20: Salmo trutta | Y20: Trucha café | Z20: 2 | AA20: 7.5 | AB20: 10 | AC20: 8.8 | AD20: 1.8 | AE20: 2 | AF20: 8.6 | AG20: 10 | AH20: 9.3 | AI20: 0.96
A21: R.EX N°767/2014 | B21: GAMAN LIMNO STUDIES LTDA. | C21: CENTRAL HIDROELECTRICA CHAICA | D21: INGENIUM CIVIL S.A | E21: =INDEX(Sheet1!$E$23:$E$34,MATCH(A21,Sheet1!$D$23:$D$34,0)) -> Gaman Limno Studies Ltda. (2014) Informe de resutados de pesca de investigación asociado al permiso SUBPESCA, R.EX N°767/2014. Proyecto: Estudio Línea base de tipo limnológico del proyecto hidroeléctrico Chaica en el río Lenca, comuna de Puerto Montt, X Región. Mandante: Ingenium Civil S.A | F21: PRIVADA | G21: CHAICA | H21: JULIO | I21: 2014 | J21: 0.35416667 | K21: E4 | L21: 41°36'29.23"S | M21: 72°39'9.66"O | N21: Actinopterygii | O21: Salmo salar | P21: Salmón del Atlántico | Q21: 1 | R21: 1. PESCA ELÉCTRICA | S21: 1 | T21: (IND/HORA) | U21: 0 | V21: NO | W21: NO | X21: Salmo salar | Y21: Salmón del Atlántico | Z21: 1 | AA21: 2.2 | AB21: 2.2 | AC21: 2.2 | AD21: - | AE21: 1 | AF21: 5.6 | AG21: 5.6 | AH21: 5.6 | AI21: -
A22: R.EX N°767/2014 | B22: GAMAN LIMNO STUDIES LTDA. | C22: CENTRAL HIDROELECTRICA CHAICA | D22: INGENIUM CIVIL S.A | E22: =INDEX(Sheet1!$E$23:$E$34,MATCH(A22,Sheet1!$D$23:$D$34,0)) -> Gaman Limno Studies Ltda. (2014) Informe de resutados de pesca de investigación asociado al permiso SUBPESCA, R.EX N°767/2014. Proyecto: Estudio Línea base de tipo limnológico del proyecto hidroeléctrico Chaica en el río Lenca, comuna de Puerto Montt, X Región. Mandante: Ingenium Civil S.A | F22: PRIVADA | G22: CHAICA | H22: JULIO | I22: 2014 | J22: 0.35416667 | K22: E4 | L22: 41°36'29.23"S | M22: 72°39'9.66"O | N22: Actinopterygii | O22: Salmo salar | P22: Salmón del Atlántico | Q22: 1 | R22: 2. ESPINEL | S22: 0.008 | T22: (IND/N°ANZ/HORA) | U22: 0 | V22: NO | W22: NO | X22: Salmo salar | Y22: Salmón del Atlántico | Z22: 1 | AA22: 320 | AB22: 320 | AC22: 320 | AD22: - | AE22: 1 | AF22: 29.5 | AG22: 29.5 | AH22: 29.5 | AI22: -
A23: R.EX N°767/2014 | B23: GAMAN LIMNO STUDIES LTDA. | C23: CENTRAL HIDROELECTRICA CHAICA | D23: INGENIUM CIVIL S.A | E23: =INDEX(Sheet1!$E$23:$E$34,MATCH(A23,Sheet1!$D$23:$D$34,0)) -> Gaman Limno Studies Ltda. (2014) Informe de resutados de pesca de investigación asociado al permiso SUBPESCA, R.EX N°767/2014. Proyecto: Estudio Línea base de tipo limnológico del proyecto hidroeléctrico Chaica en el río Lenca, comuna de Puerto Montt, X Región. Mandante: Ingenium Civil S.A | F23: PRIVADA | G23: CHAICA | H23: JULIO | I23: 2014 | J23: 0.35416667 | K23: E4 | L23: 41°36'29.23"S | M23: 72°39'9.66"O | N23: Actinopterygii | O23: Salmo trutta | P23: Trucha café | Q23: 1 | R23: 1. PESCA ELÉCTRICA | S23: 1 | T23: (IND/HORA) | U23: 0 | V23: NO | W23: NO | X23: Salmo trutta | Y23: Trucha café | Z23: 1 | AA23: 3.2 | AB23: 3.2 | AC23: 3.2 | AD23: - | AE23: 1 | AF23: 6.3 | AG23: 6.3 | AH23: 6.3 | AI23: -
A24: R.EX N°767/2014 | B24: GAMAN LIMNO STUDIES LTDA. | C24: CENTRAL HIDROELECTRICA CHAICA | D24: INGENIUM CIVIL S.A | E24: =INDEX(Sheet1!$E$23:$E$34,MATCH(A24,Sheet1!$D$23:$D$34,0)) -> Gaman Limno Studies Ltda. (2014) Informe de resutados de pesca de investigación asociado al permiso SUBPESCA, R.EX N°767/2014. Proyecto: Estudio Línea base de tipo limnológico del proyecto hidroeléctrico Chaica en el río Lenca, comuna de Puerto Montt, X Región. Mandante: Ingenium Civil S.A | F24: PRIVADA | G24: CHAICA | H24: JULIO | I24: 2014 | J24: 0.375 | K24: E5 | L24: 41°36'38.76"S | M24: 72°39'14.32"O | N24: Actinopterygii | O24: Galaxias maculatus | P24: Puye | Q24: 2 | R24: 1. PESCA ELÉCTRICA | S24: 2 | T24: (IND/HORA) | U24: 0 | V24: NO | W24: NO | X24: Galaxias maculatus | Y24: Puye | Z24: 2 | AA24: 1.8 | AB24: 2.5 | AC24: 2.2 | AD24: 0.49 | AE24: 2 | AF24: 7.1 | AG24: 7.8 | AH24: 7.5 | AI24: 0.49
A25: R.EX N°3232/2016 | B25: CLAUDIA VERDUGO CASTRO (ECOSISTEMA) | C25: PISCICULTURA DE RECIRCULACIÓN LAGO BALMACEDA, SEALAND AQUACULTURE S.A. RESPUESTA OBSERVACIÓN 1.2.8 ICSARA N°1 (064/2016) | D25: SEALAND AQUACULTURE S.A. | E25: =INDEX(Sheet1!$E$23:$E$34,MATCH(A25,Sheet1!$D$23:$D$34,0)) -> Claudia Verdugo Castro (Ecosistema) (2016) Informe de resutados de pesca de investigación asociado al permiso SUBPESCA, R.EX N°3232/2016. Proyecto: Piscicultura de recirculación lago Balmaceda, Sealand Aquaculture S.A.; respuesta observación 1.2.8 ICSARA n°1 (064/2016). Mandante: Sealand Aquaculture S.A. | F25: PRIVADA | G25: RÍO HOLLEMBERG | H25: JULIO | I25: 2017 | J25: - | K25: E4 | L25: 675275 | M25: 4246233 | N25: PECES | O25: Oncorhynchus tshawyttscha | P25: Salmón chinook | Q25: 1 | R25: PROSPECCIÓN VISUAL | S25: - | T25: - | U25: - | V25: - | W25: - | X25: Oncorhynchus tshawyttscha | Y25: Salmón chinook | Z25: - | AA25: - | AB25: - | AC25: - | AD25: - | AE25: - | AF25: - | AG25: - | AH25: - | AI25: -
A26: R. EX N°388/2018 | B26: ICNOVA ING CONSULTORES | C26: Diagnostico Hidrobiológico de Laguna Escondida y Laguna Barrosa - Declaración de Impacto Ambiental Almacenamiento de Agua de Interior Mina Javiera en Laguna Salitrosa, Comuna de Chile Chico, XII Región de Aysén | D26: Compañía Minera Cerro Bayo Ltda | E26: =INDEX(Sheet1!$E$23:$E$34,MATCH(A26,Sheet1!$D$23:$D$34,0)) -> Icnova Ing Consultores (2018) Informe de resutados de pesca de investigación asociado al permiso SUBPESCA, R. EX N°388/2018. Proyecto: Diagnostico hidrobiológico de laguna Escondida y laguna Barrosa - declaración de impacto ambiental almacenamiento de agua de interior Mina Javiera en laguna Salitrosa, comuna de Chile Chico, XII Región de Aysén. Mandante: Compañía Minera Cerro Bayo Ltda. | F26: PRIVADA | G26: Costeras entre Rio Jeinemeni y Rio San Jose | H26: FEBRERO | I26: 2018 | J26: - | K26: Laguna Barrosa | L26: 46°31'32.38''S | M26: 71°50'43.89''W | N26: PECES | O26: Odonthestes hatcheri | P26: Cauque patagonico | Q26: 35 | R26: Pesca eléctrica (SAMU) | S26: - | T26: - | U26: - | V26: - | W26: - | X26: Odonthestes hatcheri | Y26: Cauque patagonico | Z26: 35 | AA26: - | AB26: - | AC26: - | AD26: - | AE26: 35 | AF26: 9.3 | AG26: 15.5 | AH26: 11.9 | AI26: -
A27: R. EX N°388/2018 | B27: ICNOVA ING CONSULTORES | C27: Diagnostico Hidrobiológico de Laguna Escondida y Laguna Barrosa - Declaración de Impacto Ambiental Almacenamiento de Agua de Interior Mina Javiera en Laguna Salitrosa, Comuna de Chile Chico, XII Región de Aysén | D27: Compañía Minera Cerro Bayo Ltda | E27: =INDEX(Sheet1!$E$23:$E$34,MATCH(A27,Sheet1!$D$23:$D$34,0)) -> Icnova Ing Consultores (2018) Informe de resutados de pesca de investigación asociado al permiso SUBPESCA, R. EX N°388/2018. Proyecto: Diagnostico hidrobiológico de laguna Escondida y laguna Barrosa - declaración de impacto ambiental almacenamiento de agua de interior Mina Javiera en laguna Salitrosa, comuna de Chile Chico, XII Región de Aysén. Mandante: Compañía Minera Cerro Bayo Ltda. | F27: PRIVADA | G27: Costeras entre Rio Jeinemeni y Rio San Jose | H27: FEBRERO | I27: 2018 | J27: - | K27: Laguna Escondida | L27: 46°31'0.40''S | M27: 71°50'40.24''W | N27: PECES | O27: Odonthestes hatcheri | P27: Cauque patagonico | Q27: 14 | R27: Pesca eléctrica (SAMU) | S27: - | T27: - | U27: - | V27: - | W27: - | X27: Odonthestes hatcheri | Y27: Cauque patagonico | Z27: 14 | AA27: - | AB27: - | AC27: - | AD27: - | AE27: 14 | AF27: 7.6 | AG27: 11 | AH27: 10.3 | AI27: -
A28: R. EX N°838/2018 | B28: ICNOVA ING | C28: Proyecto de riego Magallanes, embalse río Porvenir | D28: Comisión Nacional de Riego | E28: =INDEX(Sheet1!$E$23:$E$34,MATCH(A28,Sheet1!$D$23:$D$34,0)) -> Icnova Ing (2018) Informe de resutados de pesca de investigación asociado al permiso SUBPESCA, R. EX N°838/2018. Proyecto: Caracterización limnológica asociado al proyecto de riego Magallanes, embalse río Porvenir, XII region de Magallanes y la Antártica Chilena. Mandante: Comisión Nacional de Riego. | F28: PUBLICA | G28: Tierra del Fuego | H28: ABRIL | I28: 2018 | J28: 0.6875 | K28: LI-02 | L28: -53.312391 | M28: -70.246618 | N28: PECES | O28: Galaxias platei | P28: Puye | Q28: 1 | R28: 1. PESCA ELÉCTRICA | S28: 2 | T28: (IND/HORA) | U28: - | V28: NO | W28: NO | X28: Galaxias platei | Y28: Puye | Z28: 1 | AA28: 10 | AB28: 10 | AC28: 10 | AD28: 0 | AE28: 1 | AF28: 8 | AG28: 8 | AH28: 8 | AI28: 0
A29: R. EX N°838/2018 | B29: ICNOVA ING | C29: Proyecto de riego Magallanes, embalse río Porvenir | D29: Comisión Nacional de Riego | E29: =INDEX(Sheet1!$E$23:$E$34,MATCH(A29,Sheet1!$D$23:$D$34,0)) -> Icnova Ing (2018) Informe de resutados de pesca de investigación asociado al permiso SUBPESCA, R. EX N°838/2018. Proyecto: Caracterización limnológica asociado al proyecto de riego Magallanes, embalse río Porvenir, XII region de Magallanes y la Antártica Chilena. Mandante: Comisión Nacional de Riego. | F29: PUBLICA | G29: Tierra del Fuego | H29: ABRIL | I29: 2018 | J29: 0.52083333 | K29: LI-03 | L29: -53.372786 | M29: -70.259158 | N29: PECES | O29: Galaxias platei | P29: Puye | Q29: 2 | R29: 1. PESCA ELÉCTRICA | S29: 4 | T29: (IND/HORA) | U29: - | V29: NO | W29: NO | X29: Galaxias platei | Y29: Puye | Z29: 2 | AA29: 0.5 | AB29: 0.8 | AC29: 0.65 | AD29: 0.21213203 | AE29: 2 | AF29: 7 | AG29: 7 | AH29: 7 | AI29: 0
A30: R. EX N°838/2018 | B30: ICNOVA ING | C30: Proyecto de riego Magallanes, embalse río Porvenir | D30: Comisión Nacional de Riego | E30: =INDEX(Sheet1!$E$23:$E$34,MATCH(A30,Sheet1!$D$23:$D$34,0)) -> Icnova Ing (2018) Informe de resutados de pesca de investigación asociado al permiso SUBPESCA, R. EX N°838/2018. Proyecto: Caracterización limnológica asociado al proyecto de riego Magallanes, embalse río Porvenir, XII region de Magallanes y la Antártica Chilena. Mandante: Comisión Nacional de Riego. | F30: PUBLICA | G30: Tierra del Fuego | H30: ABRIL | I30: 2018 | J30: 0.52083333 | K30: LI-03 | L30: -53.372786 | M30: -70.259158 | N30: PECES | O30: Onchorynchus mykiss | P30: Trucha arcoiris | Q30: 1 | R30: 1. PESCA ELÉCTRICA | S30: 2 | T30: (IND/HORA) | U30: - | V30: NO | W30: NO | X30: Onchorynchus mykiss | Y30: Trucha arcoiris | Z30: 1 | AA30: 20 | AB30: 20 | AC30: 20 | AD30: 0 | AE30: 1 | AF30: 15 | AG30: 15 | AH30: 15 | AI30: 0
A31: R.EX N°1628/2019 | B31: MARTINEZ AMBIENTAL LTDA | C31: MINA INVIERNO | D31: MINERA INVIERNO SA | E31: =INDEX(Sheet1!$E$23:$E$34,MATCH(A31,Sheet1!$D$23:$D$34,0)) -> Martinez Ambiental Ltda (2019) Informe de resutados de pesca de investigación asociado al permiso SUBPESCA, R.EX N°1628/2019. Proyecto: Plan de vigilancia ambiental, asociado al proyecto Mina Invierno, comuna de Río Verde, región de Magallanes y Antártica Chilena. Mandante: Minera Invierno Sa. | F31: PRIVADA | G31: ESTERO CHORRILLO INVIERNO N° 3 | H31: AGOSTO | I31: 2019 | J31: 9:00 - 16:00 HRS | K31: CH-5 | L31: 319773 | M31: 4139516 | N31: Galaxiidae | O31: Galaxias Maculatus | P31: Puye Chico | Q31: 4 | R31: 1. PESCA ELÉCTRICA | S31: 2 | T31: (IND/HORA) | U31: 0 | V31: NO | X31: Galaxias Maculatus | Y31: Puye Chico | Z31: 4 | AE31: 4
A32: R.EX N°1628/2019 | B32: MARTINEZ AMBIENTAL LTDA | C32: MINA INVIERNO | D32: MINERA INVIERNO SA | E32: =INDEX(Sheet1!$E$23:$E$34,MATCH(A32,Sheet1!$D$23:$D$34,0)) -> Martinez Ambiental Ltda (2019) Informe de resutados de pesca de investigación asociado al permiso SUBPESCA, R.EX N°1628/2019. Proyecto: Plan de vigilancia ambiental, asociado al proyecto Mina Invierno, comuna de Río Verde, región de Magallanes y Antártica Chilena. Mandante: Minera Invierno Sa. | F32: PRIVADA | G32: ESTERO CHORRILLO INVIERNO N° 3 | H32: AGOSTO | I32: 2019 | J32: 9:00 - 16:00 HRS | K32: CH-6 | L32: 319742 | M32: 4138844 | N32: Galaxiidae | O32: Galaxias Maculatus | P32: Puye Chico | Q32: 2 | R32: 1. PESCA ELÉCTRICA | S32: 1 | T32: (IND/HORA) | U32: 0 | V32: NO | W32: NO | X32: Galaxias Maculatus | Y32: Puye Chico | Z32: 2 | AE32: 2
A33: R.EX N°1628/2019 | B33: MARTINEZ AMBIENTAL LTDA | C33: MINA INVIERNO | D33: MINERA INVIERNO SA | E33: =INDEX(Sheet1!$E$23:$E$34,MATCH(A33,Sheet1!$D$23:$D$34,0)) -> Martinez Ambiental Ltda (2019) Informe de resutados de pesca de investigación asociado al permiso SUBPESCA, R.EX N°1628/2019. Proyecto: Plan de vigilancia ambiental, asociado al proyecto Mina Invierno, comuna de Río Verde, región de Magallanes y Antártica Chilena. Mandante: Minera Invierno Sa. | F33: PRIVADA | G33: ESTERO CHORRILLO INVIERNO N° 3 | H33: AGOSTO | I33: 2019 | J33: 9:00 - 16:00 HRS | K33: CH-6 | L33: 319742 | M33: 4138844 | N33: Salmonidae | O33: Salmo trutta | P33: Trucha Café | Q33: 2 | R33: 1. PESCA ELÉCTRICA | S33: 1 | T33: (IND/HORA) | U33: 0 | V33: NO | W33: NO | X33: Salmo trutta | Y33: Trucha Café | Z33: 2 | AE33: 2
A34: R.EX N°1628/2019 | B34: MARTINEZ AMBIENTAL LTDA | C34: MINA INVIERNO | D34: MINERA INVIERNO SA | E34: =INDEX(Sheet1!$E$23:$E$34,MATCH(A34,Sheet1!$D$23:$D$34,0)) -> Martinez Ambiental Ltda (2019) Informe de resutados de pesca de investigación asociado al permiso SUBPESCA, R.EX N°1628/2019. Proyecto: Plan de vigilancia ambiental, asociado al proyecto Mina Invierno, comuna de Río Verde, región de Magallanes y Antártica Chilena. Mandante: Minera Invierno Sa. | F34: PRIVADA | G34: ESTERO CHORRILLO INVIERNO N° 3 | H34: AGOSTO | I34: 2019 | J34: 9:00 - 16:00 HRS | K34: CH-8 | L34: 322207 | M34: 4135138 | N34: Salmonidae | O34: Salmo trutta | P34: Trucha Café | Q34: 1 | R34: 1. PESCA ELÉCTRICA | S34: 0.5 | T34: (IND/HORA) | U34: 0 | V34: NO | W34: NO | X34: Salmo trutta | Y34: Trucha Café | Z34: 1 | AE34: 1
A35: R.EX N°1628/2019 | B35: MARTINEZ AMBIENTAL LTDA | C35: MINA INVIERNO | D35: MINERA INVIERNO SA | E35: =INDEX(Sheet1!$E$23:$E$34,MATCH(A35,Sheet1!$D$23:$D$34,0)) -> Martinez Ambiental Ltda (2019) Informe de resutados de pesca de investigación asociado al permiso SUBPESCA, R.EX N°1628/2019. Proyecto: Plan de vigilancia ambiental, asociado al proyecto Mina Invierno, comuna de Río Verde, región de Magallanes y Antártica Chilena. Mandante: Minera Invierno Sa. | F35: PRIVADA | G35: ESTERO CHORRILLO INVIERNO N° 3 | H35: NOVIEMBRE | I35: 2019 | J35: 9:00 - 16:00 HRS | K35: CH-5 | L35: 319773 | M35: 4139516 | N35: Galaxiidae | O35: Galaxias Maculatus | P35: Puye Chico | Q35: 7 | R35: 1. PESCA ELÉCTRICA | S35: 3.5 | T35: (IND/HORA) | U35: 0 | V35: NO | W35: NO | X35: Galaxias Maculatus | Y35: Puye Chico | Z35: 7 | AE35: 7
A36: R.EX N°1628/2019 | B36: MARTINEZ AMBIENTAL LTDA | C36: MINA INVIERNO | D36: MINERA INVIERNO SA | E36: =INDEX(Sheet1!$E$23:$E$34,MATCH(A36,Sheet1!$D$23:$D$34,0)) -> Martinez Ambiental Ltda (2019) Informe de resutados de pesca de investigación asociado al permiso SUBPESCA, R.EX N°1628/2019. Proyecto: Plan de vigilancia ambiental, asociado al proyecto Mina Invierno, comuna de Río Verde, región de Magallanes y Antártica Chilena. Mandante: Minera Invierno Sa. | F36: PRIVADA | G36: ESTERO CHORRILLO INVIERNO N° 3 | H36: NOVIEMBRE | I36: 2019 | J36: 9:00 - 16:00 HRS | K36: CH-6 | L36: 319742 | M36: 4138844 | N36: Salmonidae | O36: Salmo trutta | P36: Trucha Café | Q36: 3 | R36: 1. PESCA ELÉCTRICA | S36: 1.5 | T36: (IND/HORA) | U36: 0 | V36: NO | W36: NO | X36: Salmo trutta | Y36: Trucha Café | Z36: 3 | AE36: 3
A37: R.EX N°1628/2019 | B37: MARTINEZ AMBIENTAL LTDA | C37: MINA INVIERNO | D37: MINERA INVIERNO SA | E37: =INDEX(Sheet1!$E$23:$E$34,MATCH(A37,Sheet1!$D$23:$D$34,0)) -> Martinez Ambiental Ltda (2019) Informe de resutados de pesca de investigación asociado al permiso SUBPESCA, R.EX N°1628/2019. Proyecto: Plan de vigilancia ambiental, asociado al proyecto Mina Invierno, comuna de Río Verde, región de Magallanes y Antártica Chilena. Mandante: Minera Invierno Sa. | F37: PRIVADA | G37: ESTERO CHORRILLO INVIERNO N° 3 | H37: NOVIEMBRE | I37: 2019 | J37: 9:00 - 16:00 HRS | K37: CH-7 | L37: 320743 | M37: 4136965 | N37: Salmonidae | O37: Salmo trutta | P37: Trucha Café | Q37: 2 | R37: 1. PESCA ELÉCTRICA | S37: 1 | T37: (IND/HORA) | U37: 0 | V37: NO | W37: NO | X37: Salmo trutta | Y37: Trucha Café | Z37: 2 | AE37: 2
A38: R.EX N°1628/2019 | B38: MARTINEZ AMBIENTAL LTDA | C38: MINA INVIERNO | D38: MINERA INVIERNO SA | E38: =INDEX(Sheet1!$E$23:$E$34,MATCH(A38,Sheet1!$D$23:$D$34,0)) -> Martinez Ambiental Ltda (2019) Informe de resutados de pesca de investigación asociado al permiso SUBPESCA, R.EX N°1628/2019. Proyecto: Plan de vigilancia ambiental, asociado al proyecto Mina Invierno, comuna de Río Verde, región de Magallanes y Antártica Chilena. Mandante: Minera Invierno Sa. | F38: PRIVADA | G38: ESTERO CHORRILLO INVIERNO N° 3 | H38: FEBRERO | I38: 2020 | J38: 9:00 - 16:00 HRS | K38: CH-5 | L38: 319773 | M38: 4139516 | N38: Salmonidae | O38: Salmo trutta | P38: Trucha Café | Q38: 11 | R38: 1. PESCA ELÉCTRICA | S38: 5.5 | T38: (IND/HORA) | U38: 2 | V38: NO | W38: NO | X38: Salmo trutta | Y38: Trucha Café | Z38: 11 | AE38: 11
A39: R.EX N°1628/2019 | B39: MARTINEZ AMBIENTAL LTDA | C39: MINA INVIERNO | D39: MINERA INVIERNO SA | E39: =INDEX(Sheet1!$E$23:$E$34,MATCH(A39,Sheet1!$D$23:$D$34,0)) -> Martinez Ambiental Ltda (2019) Informe de resutados de pesca de investigación asociado al permiso SUBPESCA, R.EX N°1628/2019. Proyecto: Plan de vigilancia ambiental, asociado al proyecto Mina Invierno, comuna de Río Verde, región de Magallanes y Antártica Chilena. Mandante: Minera Invierno Sa. | F39: PRIVADA | G39: ESTERO CHORRILLO INVIERNO N° 3 | H39: FEBRERO | I39: 2020 | J39: 9:00 - 16:00 HRS | K39: CH-5 | L39: 319773 | M39: 4139516 | N39: Galaxiidae | O39: Galaxias Maculatus | P39: Puye Chico | Q39: 1 | R39: 1. PESCA ELÉCTRICA | S39: 0.5 | T39: (IND/HORA) | U39: 0 | V39: NO | W39: NO | X39: Galaxias Maculatus | Y39: Puye Chico | Z39: 1 | AE39: 1
A40: R.EX N°1628/2019 | B40: MARTINEZ AMBIENTAL LTDA | C40: MINA INVIERNO | D40: MINERA INVIERNO SA | E40: =INDEX(Sheet1!$E$23:$E$34,MATCH(A40,Sheet1!$D$23:$D$34,0)) -> Martinez Ambiental Ltda (2019) Informe de resutados de pesca de investigación asociado al permiso SUBPESCA, R.EX N°1628/2019. Proyecto: Plan de vigilancia ambiental, asociado al proyecto Mina Invierno, comuna de Río Verde, región de Magallanes y Antártica Chilena. Mandante: Minera Invierno Sa. | F40: PRIVADA | G40: ESTERO CHORRILLO INVIERNO N° 3 | H40: FEBRERO | I40: 2020 | J40: 9:00 - 16:00 HRS | K40: CH-6 | L40: 319742 | M40: 4138844 | N40: Salmonidae | O40: Salmo trutta | P40: Trucha Café | Q40: 8 | R40: 1. PESCA ELÉCTRICA | S40: 4 | T40: (IND/HORA) | U40: 1 | V40: NO | W40: NO | X40: Salmo trutta | Y40: Trucha Café | Z40: 8 | AE40: 8
...
