Workbook

Sheet Matriz de homologacion
B1: En esta página se intersectan dos tablas creando una matriz de homologación de campos. Por una parte, se incluye un tabla (destacada en azul) de campos del Darwin Core Standard (DwC) con definiciones, etiquetas y ejemplos (ver fuente en hoja "DwC field vocabulary"). Esta tabla contiene 179 campos (https://github.com/tdwg/dwc/blob/master/vocabulary/term_versions.csv) de los cuales una frcción (c. 30) fue etiquetada con algún grado de prioridad para los efectos de este proyecto, especialmente aquellos destacados por la red GBIF como campos primarios y campos obligatorios (columna "Prioridad campo (MB_CC)". Por otra parte, se incluye una tabla (verde) con cerca de una decena de conjuntos de datos de registros de peces que intentamos consolidar en una sola base de datos. Los conjuntos de datos fueros listados en columnas, y sus descriptores en filas. Una tercera tabla (naranjo) consiste en la intersección de las dos tablas anteriores, que conforma la tabla de homologación. En esta, se especifica el nombre de cada campo de cada conjunto de datos en la fila que corresponde al nombre de campo del DwC. De este modo se documentan la forma en que los distintos conjuntos de datos fueron combinados en una base de datos que cumple con el DwC.
I3: Priority | J3: 1 | K3: 2 | L3: 3 | M3: 3 | N3: 4 | O3: 5 | P3: 6 | Q3: 7 | R3: 8 | S3: 9
I4: Database Name | J4: Fish Database_CCorrea | K4: Darwin Initiative Fish Atlas | L4: NEODATII_Dyer | M4: metaDatabase_CCorrea | O4: Base de Datos MMA | P4: Los Peces de Argentina | Q4: Cussac 2004 | R4: Pew_Mary_Aguilar | S4: Aplochiton | V4: Consolidated DB
I5: Type of Database | J5: Empírico | K5: Empírico | L5: Empírico-Colección museo | M5: Revisión biblio | O5: Revisión biblio | P5: ? | Q5: ? | R5: Bases de datos | S5: Revisión y empírico
I6: Comentarios | Q6: Fueron ingresados por Mary, salvo un punto de aplochiton
I7: Fuente o Referancia | J7: Correa & Boisjoly, base de datos y colección. | K7: Carlos García de Leániz (PI), Gonzalo Gajardo, et al. Department for Environment Food and Rural Affairs (DEFRA, UK). Darwin Initiative Grants 15020 and EIDPO041.
I8: Número de registros totales
I9: Número de registros exclusivos
A10: Capos del DwC numerados | B10: Darwin Core Terms (DwC) | C10: label (DwC) | D10: Prioridad campo (MB_CC) | E10: status (DwC) | F10: definition (DwC) | G10: comments (DwC) | H10: example (DwC)
A11: 1 | B11: type | C11: =INDEX('DwC attribute vocabulary'!$D$3:$D$903,MATCH(B11,'DwC attribute vocabulary'!$C$3:$C$903, 0)) -> Type | E11: =INDEX('DwC attribute vocabulary'!$J$3:$J$903,MATCH(B11,'DwC attribute vocabulary'!$C$3:$C$903, 0)) -> recommended | F11: =INDEX('DwC attribute vocabulary'!$E$3:$E$903,MATCH(B11,'DwC attribute vocabulary'!$C$3:$C$903, 0)) -> The nature or genre of the resource. | G11: =INDEX('DwC attribute vocabulary'!$F$3:$F$903,MATCH($B11,'DwC attribute vocabulary'!$C$3:$C$903, 0)) -> Must be populated with a value from the DCMI type vocabulary (http://dublincore.org/documents/2010/10/11/dcmi-type-vocabulary/). | H11: =INDEX('DwC attribute vocabulary'!$G$3:$G$903,MATCH($B11,'DwC attribute vocabulary'!$C$3:$C$903, 0)) -> `StillImage`; `MovingImage`; `Sound`; `PhysicalObject`; `Event`; `Text`
A12: 2 | B12: modified | C12: =INDEX('DwC attribute vocabulary'!$D$3:$D$903,MATCH(B12,'DwC attribute vocabulary'!$C$3:$C$903, 0)) -> Date Modified | E12: =INDEX('DwC attribute vocabulary'!$J$3:$J$903,MATCH(B12,'DwC attribute vocabulary'!$C$3:$C$903, 0)) -> recommended | F12: =INDEX('DwC attribute vocabulary'!$E$3:$E$903,MATCH(B12,'DwC attribute vocabulary'!$C$3:$C$903, 0)) -> The most recent date-time on which the resource was changed. | G12: =INDEX('DwC attribute vocabulary'!$F$3:$F$903,MATCH($B12,'DwC attribute vocabulary'!$C$3:$C$903, 0)) -> Recommended best practice is to use a date that conforms to ISO 8601-1:2019. | H12: =INDEX('DwC attribute vocabulary'!$G$3:$G$903,MATCH($B12,'DwC attribute vocabulary'!$C$3:$C$903, 0)) -> `1963-03-08T14:07-0600` (8 Mar 1963 at 2:07pm in the time zone six hours earlier than UTC); `2009-02-20T08:40Z` (20 February 2009 8:40am UTC); `2018-08-29T15:19` (3:19pm local time on 29 August 2018); `1809-02-12` (some time during 12 February 1809); `1906-06` (some time in June 1906); `1971` (some time in the year 1971); `2007-03-01T13:00:00Z/2008-05-11T15:30:00Z` (some time during the interval between 1 March 2007 1pm UTC and 11 May 2008 3:30pm UTC); `1900/1909` (some time during the interval between the beginning of the year 1900 and the end of the year 1909); `2007-11-13/15` (some time in the interval between 13 November 2007 and 15 November 2007)
A13: 3 | B13: language | C13: =INDEX('DwC attribute vocabulary'!$D$3:$D$903,MATCH(B13,'DwC attribute vocabulary'!$C$3:$C$903, 0)) -> Language | E13: =INDEX('DwC attribute vocabulary'!$J$3:$J$903,MATCH(B13,'DwC attribute vocabulary'!$C$3:$C$903, 0)) -> recommended | F13: =INDEX('DwC attribute vocabulary'!$E$3:$E$903,MATCH(B13,'DwC attribute vocabulary'!$C$3:$C$903, 0)) -> A language of the resource. | G13: =INDEX('DwC attribute vocabulary'!$F$3:$F$903,MATCH($B13,'DwC attribute vocabulary'!$C$3:$C$903, 0)) -> Recommended best practice is to use a controlled vocabulary such as RFC 5646. | H13: =INDEX('DwC attribute vocabulary'!$G$3:$G$903,MATCH($B13,'DwC attribute vocabulary'!$C$3:$C$903, 0)) -> `en` (for English); `es` (for Spanish)
A14: 4 | B14: license | C14: =INDEX('DwC attribute vocabulary'!$D$3:$D$903,MATCH(B14,'DwC attribute vocabulary'!$C$3:$C$903, 0)) -> License | D14: Include if necessary | E14: =INDEX('DwC attribute vocabulary'!$J$3:$J$903,MATCH(B14,'DwC attribute vocabulary'!$C$3:$C$903, 0)) -> recommended | F14: =INDEX('DwC attribute vocabulary'!$E$3:$E$903,MATCH(B14,'DwC attribute vocabulary'!$C$3:$C$903, 0)) -> A legal document giving official permission to do something with the resource. | G14: =INDEX('DwC attribute vocabulary'!$F$3:$F$903,MATCH($B14,'DwC attribute vocabulary'!$C$3:$C$903, 0)) -> 0 | H14: =INDEX('DwC attribute vocabulary'!$G$3:$G$903,MATCH($B14,'DwC attribute vocabulary'!$C$3:$C$903, 0)) -> `http://creativecommons.org/publicdomain/zero/1.0/legalcode`; `http://creativecommons.org/licenses/by/4.0/legalcode`
A15: 5 | B15: rightsHolder | C15: =INDEX('DwC attribute vocabulary'!$D$3:$D$903,MATCH(B15,'DwC attribute vocabulary'!$C$3:$C$903, 0)) -> Rights Holder | D15: Include if possible | E15: =INDEX('DwC attribute vocabulary'!$J$3:$J$903,MATCH(B15,'DwC attribute vocabulary'!$C$3:$C$903, 0)) -> recommended | F15: =INDEX('DwC attribute vocabulary'!$E$3:$E$903,MATCH(B15,'DwC attribute vocabulary'!$C$3:$C$903, 0)) -> A person or organization owning or managing rights over the resource. | G15: =INDEX('DwC attribute vocabulary'!$F$3:$F$903,MATCH($B15,'DwC attribute vocabulary'!$C$3:$C$903, 0)) -> 0 | H15: =INDEX('DwC attribute vocabulary'!$G$3:$G$903,MATCH($B15,'DwC attribute vocabulary'!$C$3:$C$903, 0)) -> `The Regents of the University of California`
A16: 6 | B16: accessRights | C16: =INDEX('DwC attribute vocabulary'!$D$3:$D$903,MATCH(B16,'DwC attribute vocabulary'!$C$3:$C$903, 0)) -> Access Rights | D16: Include if necessary | E16: =INDEX('DwC attribute vocabulary'!$J$3:$J$903,MATCH(B16,'DwC attribute vocabulary'!$C$3:$C$903, 0)) -> recommended | F16: =INDEX('DwC attribute vocabulary'!$E$3:$E$903,MATCH(B16,'DwC attribute vocabulary'!$C$3:$C$903, 0)) -> Information about who can access the resource or an indication of its security status. | G16: =INDEX('DwC attribute vocabulary'!$F$3:$F$903,MATCH($B16,'DwC attribute vocabulary'!$C$3:$C$903, 0)) -> Access Rights may include information regarding access or restrictions based on privacy, security, or other policies. | H16: =INDEX('DwC attribute vocabulary'!$G$3:$G$903,MATCH($B16,'DwC attribute vocabulary'!$C$3:$C$903, 0)) -> `not-for-profit use only`; `https://www.fieldmuseum.org/field-museum-natural-history-conditions-and-suggested-norms-use-collections-data-and-images`
A17: 7 | B17: bibliographicCitation | C17: =INDEX('DwC attribute vocabulary'!$D$3:$D$903,MATCH(B17,'DwC attribute vocabulary'!$C$3:$C$903, 0)) -> Bibliographic Citation | D17: Include if possible | E17: =INDEX('DwC attribute vocabulary'!$J$3:$J$903,MATCH(B17,'DwC attribute vocabulary'!$C$3:$C$903, 0)) -> recommended | F17: =INDEX('DwC attribute vocabulary'!$E$3:$E$903,MATCH(B17,'DwC attribute vocabulary'!$C$3:$C$903, 0)) -> A bibliographic reference for the resource as a statement indicating how this record should be cited (attributed) when used. | G17: =INDEX('DwC attribute vocabulary'!$F$3:$F$903,MATCH($B17,'DwC attribute vocabulary'!$C$3:$C$903, 0)) -> From Dublin Core, "Recommended practice is to include sufficient bibliographic detail to identify the resource as unambiguously as possible." The intended usage of this term in Darwin Core is to provide the preferred way to cite the resource itself - "how to cite this record". Note that the intended usage of dcterms:references in Darwin Core, by contrast, is to point to the definitive source representation of the resource - "where to find the as-close-to-original reference, if one is available. | H17: =INDEX('DwC attribute vocabulary'!$G$3:$G$903,MATCH($B17,'DwC attribute vocabulary'!$C$3:$C$903, 0)) -> Occurrence example: `Museum of Vertebrate Zoology, UC Berkeley. MVZ Mammal Collection (Arctos). Record ID: http://arctos.database.museum/guid/MVZ:Mamm:165861?seid=101356. Source: http://ipt.vertnet.org:8080/ipt/resource.do?r=mvz_mammal.`; Taxon example: `https://www.gbif.org/species/2439608 Source: GBIF Taxonomic Backbone`; Event example: `Rand, K.M., Logerwell, E.A. The first demersal trawl survey of benthic fish and invertebrates in the Beaufort Sea since the late 1970s. Polar Biol 34, 475–488 (2011). https://doi.org/10.1007/s00300-010-0900-2`
A18: 8 | B18: references | C18: =INDEX('DwC attribute vocabulary'!$D$3:$D$903,MATCH(B18,'DwC attribute vocabulary'!$C$3:$C$903, 0)) -> References | E18: =INDEX('DwC attribute vocabulary'!$J$3:$J$903,MATCH(B18,'DwC attribute vocabulary'!$C$3:$C$903, 0)) -> recommended | F18: =INDEX('DwC attribute vocabulary'!$E$3:$E$903,MATCH(B18,'DwC attribute vocabulary'!$C$3:$C$903, 0)) -> A related resource that is referenced, cited, or otherwise pointed to by the described resource. | G18: =INDEX('DwC attribute vocabulary'!$F$3:$F$903,MATCH($B18,'DwC attribute vocabulary'!$C$3:$C$903, 0)) -> From Dublin Core, "This property is intended to be used with non-literal values. This property is an inverse property of Is Referenced By." The intended usage of this term in Darwin Core is to point to the definitive source representation of the resource (e.g., Taxon, Occurrence, Event in Darwin Core), if one is available. Note that the intended usage of dcterms:bibliographicCitation in Darwin Core, by contrast, is to provide the preferred way to cite the resource itself. | H18: =INDEX('DwC attribute vocabulary'!$G$3:$G$903,MATCH($B18,'DwC attribute vocabulary'!$C$3:$C$903, 0)) -> MaterialSample example: `http://arctos.database.museum/guid/MVZ:Mamm:165861`; Taxon example: `https://www.catalogueoflife.org/data/taxon/32664`
A19: 9 | B19: institutionID | C19: =INDEX('DwC attribute vocabulary'!$D$3:$D$903,MATCH(B19,'DwC attribute vocabulary'!$C$3:$C$903, 0)) -> Institution ID | D19: For voucher specimens | E19: =INDEX('DwC attribute vocabulary'!$J$3:$J$903,MATCH(B19,'DwC attribute vocabulary'!$C$3:$C$903, 0)) -> recommended | F19: =INDEX('DwC attribute vocabulary'!$E$3:$E$903,MATCH(B19,'DwC attribute vocabulary'!$C$3:$C$903, 0)) -> An identifier for the institution having custody of the object(s) or information referred to in the record. | G19: =INDEX('DwC attribute vocabulary'!$F$3:$F$903,MATCH($B19,'DwC attribute vocabulary'!$C$3:$C$903, 0)) -> For physical specimens, the recommended best practice is to use an identifier from a collections registry such as the Global Registry of Biodiversity Repositories (http://grbio.org/). | H19: =INDEX('DwC attribute vocabulary'!$G$3:$G$903,MATCH($B19,'DwC attribute vocabulary'!$C$3:$C$903, 0)) -> `http://biocol.org/urn:lsid:biocol.org:col:34777`; `http://grbio.org/cool/km06-gtbn`
A20: 10 | B20: collectionID | C20: =INDEX('DwC attribute vocabulary'!$D$3:$D$903,MATCH(B20,'DwC attribute vocabulary'!$C$3:$C$903, 0)) -> Collection ID | D20: For voucher specimens | E20: =INDEX('DwC attribute vocabulary'!$J$3:$J$903,MATCH(B20,'DwC attribute vocabulary'!$C$3:$C$903, 0)) -> recommended | F20: =INDEX('DwC attribute vocabulary'!$E$3:$E$903,MATCH(B20,'DwC attribute vocabulary'!$C$3:$C$903, 0)) -> An identifier for the collection or dataset from which the record was derived. | G20: =INDEX('DwC attribute vocabulary'!$F$3:$F$903,MATCH($B20,'DwC attribute vocabulary'!$C$3:$C$903, 0)) -> For physical specimens, the recommended best practice is to use an identifier from a collections registry such as the Global Registry of Biodiversity Repositories (http://grbio.org/). | H20: =INDEX('DwC attribute vocabulary'!$G$3:$G$903,MATCH($B20,'DwC attribute vocabulary'!$C$3:$C$903, 0)) -> `http://biocol.org/urn:lsid:biocol.org:col:1001`; `http://grbio.org/cool/p5fp-c036`
A21: 11 | B21: datasetID | C21: =INDEX('DwC attribute vocabulary'!$D$3:$D$903,MATCH(B21,'DwC attribute vocabulary'!$C$3:$C$903, 0)) -> Dataset ID | E21: =INDEX('DwC attribute vocabulary'!$J$3:$J$903,MATCH(B21,'DwC attribute vocabulary'!$C$3:$C$903, 0)) -> recommended | F21: =INDEX('DwC attribute vocabulary'!$E$3:$E$903,MATCH(B21,'DwC attribute vocabulary'!$C$3:$C$903, 0)) -> An identifier for the set of data. May be a global unique identifier or an identifier specific to a collection or institution. | G21: =INDEX('DwC attribute vocabulary'!$F$3:$F$903,MATCH($B21,'DwC attribute vocabulary'!$C$3:$C$903, 0)) -> 0 | H21: =INDEX('DwC attribute vocabulary'!$G$3:$G$903,MATCH($B21,'DwC attribute vocabulary'!$C$3:$C$903, 0)) -> `b15d4952-7d20-46f1-8a3e-556a512b04c5`
A22: 12 | B22: institutionCode | C22: =INDEX('DwC attribute vocabulary'!$D$3:$D$903,MATCH(B22,'DwC attribute vocabulary'!$C$3:$C$903, 0)) -> Institution Code | D22: GBIF Primary field and necessary for GBIF indexing | E22: =INDEX('DwC attribute vocabulary'!$J$3:$J$903,MATCH(B22,'DwC attribute vocabulary'!$C$3:$C$903, 0)) -> recommended | F22: =INDEX('DwC attribute vocabulary'!$E$3:$E$903,MATCH(B22,'DwC attribute vocabulary'!$C$3:$C$903, 0)) -> The name (or acronym) in use by the institution having custody of the object(s) or information referred to in the record. | G22: =INDEX('DwC attribute vocabulary'!$F$3:$F$903,MATCH($B22,'DwC attribute vocabulary'!$C$3:$C$903, 0)) -> 0 | H22: =INDEX('DwC attribute vocabulary'!$G$3:$G$903,MATCH($B22,'DwC attribute vocabulary'!$C$3:$C$903, 0)) -> `MVZ`; `FMNH`; `CLO`; `UCMP`
A23: 13 | B23: collectionCode | C23: =INDEX('DwC attribute vocabulary'!$D$3:$D$903,MATCH(B23,'DwC attribute vocabulary'!$C$3:$C$903, 0)) -> Collection Code | D23: GBIF Primary field and necessary for GBIF indexing | E23: =INDEX('DwC attribute vocabulary'!$J$3:$J$903,MATCH(B23,'DwC attribute vocabulary'!$C$3:$C$903, 0)) -> recommended | F23: =INDEX('DwC attribute vocabulary'!$E$3:$E$903,MATCH(B23,'DwC attribute vocabulary'!$C$3:$C$903, 0)) -> The name, acronym, coden, or initialism identifying the collection or data set from which the record was derived. | G23: =INDEX('DwC attribute vocabulary'!$F$3:$F$903,MATCH($B23,'DwC attribute vocabulary'!$C$3:$C$903, 0)) -> 0 | H23: =INDEX('DwC attribute vocabulary'!$G$3:$G$903,MATCH($B23,'DwC attribute vocabulary'!$C$3:$C$903, 0)) -> `Mammals`; `Hildebrandt`; `EBIRD`; `VP`
A24: 14 | B24: datasetName | C24: =INDEX('DwC attribute vocabulary'!$D$3:$D$903,MATCH(B24,'DwC attribute vocabulary'!$C$3:$C$903, 0)) -> Dataset Name | D24: Include if possible | E24: =INDEX('DwC attribute vocabulary'!$J$3:$J$903,MATCH(B24,'DwC attribute vocabulary'!$C$3:$C$903, 0)) -> recommended | F24: =INDEX('DwC attribute vocabulary'!$E$3:$E$903,MATCH(B24,'DwC attribute vocabulary'!$C$3:$C$903, 0)) -> The name identifying the data set from which the record was derived. | G24: =INDEX('DwC attribute vocabulary'!$F$3:$F$903,MATCH($B24,'DwC attribute vocabulary'!$C$3:$C$903, 0)) -> 0 | H24: =INDEX('DwC attribute vocabulary'!$G$3:$G$903,MATCH($B24,'DwC attribute vocabulary'!$C$3:$C$903, 0)) -> `Grinnell Resurvey Mammals`; `Lacey Ctenomys Recaptures`
A25: 15 | B25: ownerInstitutionCode | C25: =INDEX('DwC attribute vocabulary'!$D$3:$D$903,MATCH(B25,'DwC attribute vocabulary'!$C$3:$C$903, 0)) -> Owner Institution Code | E25: =INDEX('DwC attribute vocabulary'!$J$3:$J$903,MATCH(B25,'DwC attribute vocabulary'!$C$3:$C$903, 0)) -> recommended | F25: =INDEX('DwC attribute vocabulary'!$E$3:$E$903,MATCH(B25,'DwC attribute vocabulary'!$C$3:$C$903, 0)) -> The name (or acronym) in use by the institution having ownership of the object(s) or information referred to in the record. | G25: =INDEX('DwC attribute vocabulary'!$F$3:$F$903,MATCH($B25,'DwC attribute vocabulary'!$C$3:$C$903, 0)) -> 0 | H25: =INDEX('DwC attribute vocabulary'!$G$3:$G$903,MATCH($B25,'DwC attribute vocabulary'!$C$3:$C$903, 0)) -> `NPS`; `APN`; `InBio`
A26: 16 | B26: basisOfRecord | C26: =INDEX('DwC attribute vocabulary'!$D$3:$D$903,MATCH(B26,'DwC attribute vocabulary'!$C$3:$C$903, 0)) -> Basis of Record | D26: GBIF Primary field and necessary for GBIF indexing | E26: =INDEX('DwC attribute vocabulary'!$J$3:$J$903,MATCH(B26,'DwC attribute vocabulary'!$C$3:$C$903, 0)) -> recommended | F26: =INDEX('DwC attribute vocabulary'!$E$3:$E$903,MATCH(B26,'DwC attribute vocabulary'!$C$3:$C$903, 0)) -> The specific nature of the data record. | G26: =INDEX('DwC attribute vocabulary'!$F$3:$F$903,MATCH($B26,'DwC attribute vocabulary'!$C$3:$C$903, 0)) -> Recommended best practice is to use the standard label of one of the Darwin Core classes. | H26: =INDEX('DwC attribute vocabulary'!$G$3:$G$903,MATCH($B26,'DwC attribute vocabulary'!$C$3:$C$903, 0)) -> `PreservedSpecimen`; `FossilSpecimen`; `LivingSpecimen`; `MaterialSample`; `Event`; `HumanObservation`; `MachineObservation`; `Taxon`; `Occurrence`; `MaterialCitation`
A27: 17 | B27: informationWithheld | C27: =INDEX('DwC attribute vocabulary'!$D$3:$D$903,MATCH(B27,'DwC attribute vocabulary'!$C$3:$C$903, 0)) -> Information Withheld | E27: =INDEX('DwC attribute vocabulary'!$J$3:$J$903,MATCH(B27,'DwC attribute vocabulary'!$C$3:$C$903, 0)) -> recommended | F27: =INDEX('DwC attribute vocabulary'!$E$3:$E$903,MATCH(B27,'DwC attribute vocabulary'!$C$3:$C$903, 0)) -> Additional information that exists, but that has not been shared in the given record. | G27: =INDEX('DwC attribute vocabulary'!$F$3:$F$903,MATCH($B27,'DwC attribute vocabulary'!$C$3:$C$903, 0)) -> 0 | H27: =INDEX('DwC attribute vocabulary'!$G$3:$G$903,MATCH($B27,'DwC attribute vocabulary'!$C$3:$C$903, 0)) -> `location information not given for endangered species`; `collector identities withheld | ask about tissue samples`
A28: 18 | B28: dataGeneralizations | C28: =INDEX('DwC attribute vocabulary'!$D$3:$D$903,MATCH(B28,'DwC attribute vocabulary'!$C$3:$C$903, 0)) -> Data Generalizations | E28: =INDEX('DwC attribute vocabulary'!$J$3:$J$903,MATCH(B28,'DwC attribute vocabulary'!$C$3:$C$903, 0)) -> recommended | F28: =INDEX('DwC attribute vocabulary'!$E$3:$E$903,MATCH(B28,'DwC attribute vocabulary'!$C$3:$C$903, 0)) -> Actions taken to make the shared data less specific or complete than in its original form. Suggests that alternative data of higher quality may be available on request. | G28: =INDEX('DwC attribute vocabulary'!$F$3:$F$903,MATCH($B28,'DwC attribute vocabulary'!$C$3:$C$903, 0)) -> 0 | H28: =INDEX('DwC attribute vocabulary'!$G$3:$G$903,MATCH($B28,'DwC attribute vocabulary'!$C$3:$C$903, 0)) -> `Coordinates generalized from original GPS coordinates to the nearest half degree grid cell`
A29: 19 | B29: dynamicProperties | C29: =INDEX('DwC attribute vocabulary'!$D$3:$D$903,MATCH(B29,'DwC attribute vocabulary'!$C$3:$C$903, 0)) -> Dynamic Properties | E29: =INDEX('DwC attribute vocabulary'!$J$3:$J$903,MATCH(B29,'DwC attribute vocabulary'!$C$3:$C$903, 0)) -> recommended | F29: =INDEX('DwC attribute vocabulary'!$E$3:$E$903,MATCH(B29,'DwC attribute vocabulary'!$C$3:$C$903, 0)) -> A list of additional measurements, facts, characteristics, or assertions about the record. Meant to provide a mechanism for structured content. | G29: =INDEX('DwC attribute vocabulary'!$F$3:$F$903,MATCH($B29,'DwC attribute vocabulary'!$C$3:$C$903, 0)) -> Recommended best practice is to use a key:value encoding schema for a data interchange format such as JSON. | H29: =INDEX('DwC attribute vocabulary'!$G$3:$G$903,MATCH($B29,'DwC attribute vocabulary'!$C$3:$C$903, 0)) -> `{"heightInMeters":1.5}`; `{"tragusLengthInMeters":0.014, "weightInGrams":120}`; `{"natureOfID":"expert identification", "identificationEvidence":"cytochrome B sequence"}`; `{"relativeHumidity":28, "airTemperatureInCelsius":22, "sampleSizeInKilograms":10}`; `{"aspectHeading":277, "slopeInDegrees":6}`; `{"iucnStatus":"vulnerable", "taxonDistribution":"Neuquén, Argentina"}`
A30: 20 | B30: occurrenceID | C30: =INDEX('DwC attribute vocabulary'!$D$3:$D$903,MATCH(B30,'DwC attribute vocabulary'!$C$3:$C$903, 0)) -> Occurrence ID | D30: GBIF Primary field | E30: =INDEX('DwC attribute vocabulary'!$J$3:$J$903,MATCH(B30,'DwC attribute vocabulary'!$C$3:$C$903, 0)) -> recommended | F30: =INDEX('DwC attribute vocabulary'!$E$3:$E$903,MATCH(B30,'DwC attribute vocabulary'!$C$3:$C$903, 0)) -> An identifier for the Occurrence (as opposed to a particular digital record of the occurrence). In the absence of a persistent global unique identifier, construct one from a combination of identifiers in the record that will most closely make the occurrenceID globally unique. | G30: =INDEX('DwC attribute vocabulary'!$F$3:$F$903,MATCH($B30,'DwC attribute vocabulary'!$C$3:$C$903, 0)) -> Recommended best practice is to use a persistent, globally unique identifier. | H30: =INDEX('DwC attribute vocabulary'!$G$3:$G$903,MATCH($B30,'DwC attribute vocabulary'!$C$3:$C$903, 0)) -> `http://arctos.database.museum/guid/MSB:Mamm:233627`; `000866d2-c177-4648-a200-ead4007051b9`; `urn:catalog:UWBM:Bird:89776`
A31: 21 | B31: catalogNumber | C31: =INDEX('DwC attribute vocabulary'!$D$3:$D$903,MATCH(B31,'DwC attribute vocabulary'!$C$3:$C$903, 0)) -> Catalog Number | D31: GBIF Primary field and necessary for GBIF indexing | E31: =INDEX('DwC attribute vocabulary'!$J$3:$J$903,MATCH(B31,'DwC attribute vocabulary'!$C$3:$C$903, 0)) -> recommended | F31: =INDEX('DwC attribute vocabulary'!$E$3:$E$903,MATCH(B31,'DwC attribute vocabulary'!$C$3:$C$903, 0)) -> An identifier (preferably unique) for the record within the data set or collection. | G31: =INDEX('DwC attribute vocabulary'!$F$3:$F$903,MATCH($B31,'DwC attribute vocabulary'!$C$3:$C$903, 0)) -> 0 | H31: =INDEX('DwC attribute vocabulary'!$G$3:$G$903,MATCH($B31,'DwC attribute vocabulary'!$C$3:$C$903, 0)) -> `145732`; `145732a`; `2008.1334`; `R-4313`
A32: 22 | B32: recordNumber | C32: =INDEX('DwC attribute vocabulary'!$D$3:$D$903,MATCH(B32,'DwC attribute vocabulary'!$C$3:$C$903, 0)) -> Record Number | D32: Include if possible | E32: =INDEX('DwC attribute vocabulary'!$J$3:$J$903,MATCH(B32,'DwC attribute vocabulary'!$C$3:$C$903, 0)) -> recommended | F32: =INDEX('DwC attribute vocabulary'!$E$3:$E$903,MATCH(B32,'DwC attribute vocabulary'!$C$3:$C$903, 0)) -> An identifier given to the Occurrence at the time it was recorded. Often serves as a link between field notes and an Occurrence record, such as a specimen collector's number. | G32: =INDEX('DwC attribute vocabulary'!$F$3:$F$903,MATCH($B32,'DwC attribute vocabulary'!$C$3:$C$903, 0)) -> 0 | H32: =INDEX('DwC attribute vocabulary'!$G$3:$G$903,MATCH($B32,'DwC attribute vocabulary'!$C$3:$C$903, 0)) -> `OPP 7101`
A33: 23 | B33: recordedBy | C33: =INDEX('DwC attribute vocabulary'!$D$3:$D$903,MATCH(B33,'DwC attribute vocabulary'!$C$3:$C$903, 0)) -> Recorded By | D33: GBIF Primary field | E33: =INDEX('DwC attribute vocabulary'!$J$3:$J$903,MATCH(B33,'DwC attribute vocabulary'!$C$3:$C$903, 0)) -> recommended | F33: =INDEX('DwC attribute vocabulary'!$E$3:$E$903,MATCH(B33,'DwC attribute vocabulary'!$C$3:$C$903, 0)) -> A list (concatenated and separated) of names of people, groups, or organizations responsible for recording the original Occurrence. The primary collector or observer, especially one who applies a personal identifier (recordNumber), should be listed first. | G33: =INDEX('DwC attribute vocabulary'!$F$3:$F$903,MATCH($B33,'DwC attribute vocabulary'!$C$3:$C$903, 0)) -> Recommended best practice is to separate the values in a list with space vertical bar space (` | `). | H33: =INDEX('DwC attribute vocabulary'!$G$3:$G$903,MATCH($B33,'DwC attribute vocabulary'!$C$3:$C$903, 0)) -> `José E. Crespo`; `Oliver P. Pearson | Anita K. Pearson` (where the value in recordNumber `OPP 7101` corresponds to the collector number for the specimen in the field catalog of Oliver P. Pearson)
A34: 24 | B34: recordedByID | C34: =INDEX('DwC attribute vocabulary'!$D$3:$D$903,MATCH(B34,'DwC attribute vocabulary'!$C$3:$C$903, 0)) -> Recorded By ID | E34: =INDEX('DwC attribute vocabulary'!$J$3:$J$903,MATCH(B34,'DwC attribute vocabulary'!$C$3:$C$903, 0)) -> recommended | F34: =INDEX('DwC attribute vocabulary'!$E$3:$E$903,MATCH(B34,'DwC attribute vocabulary'!$C$3:$C$903, 0)) -> A list (concatenated and separated) of the globally unique identifier for the person, people, groups, or organizations responsible for recording the original Occurrence. | G34: =INDEX('DwC attribute vocabulary'!$F$3:$F$903,MATCH($B34,'DwC attribute vocabulary'!$C$3:$C$903, 0)) -> Recommended best practice is to provide a single identifier that disambiguates the details of the identifying agent. If a list is used, it is recommended to separate the values in the list with space vertical bar space (` | `). The order of the identifiers on any list for this term can not be guaranteed to convey any semantics. | H34: =INDEX('DwC attribute vocabulary'!$G$3:$G$903,MATCH($B34,'DwC attribute vocabulary'!$C$3:$C$903, 0)) -> `https://orcid.org/0000-0002-1825-0097` (for an individual); `https://orcid.org/0000-0002-1825-0097 | https://orcid.org/0000-0002-1825-0098` (for a list of people)
A35: 25 | B35: individualCount | C35: =INDEX('DwC attribute vocabulary'!$D$3:$D$903,MATCH(B35,'DwC attribute vocabulary'!$C$3:$C$903, 0)) -> Individual Count | D35: Include if possible | E35: =INDEX('DwC attribute vocabulary'!$J$3:$J$903,MATCH(B35,'DwC attribute vocabulary'!$C$3:$C$903, 0)) -> recommended | F35: =INDEX('DwC attribute vocabulary'!$E$3:$E$903,MATCH(B35,'DwC attribute vocabulary'!$C$3:$C$903, 0)) -> The number of individuals present at the time of the Occurrence. | G35: =INDEX('DwC attribute vocabulary'!$F$3:$F$903,MATCH($B35,'DwC attribute vocabulary'!$C$3:$C$903, 0)) -> 0 | H35: =INDEX('DwC attribute vocabulary'!$G$3:$G$903,MATCH($B35,'DwC attribute vocabulary'!$C$3:$C$903, 0)) -> `0`; `1`; `25`
A36: 26 | B36: organismQuantity | C36: =INDEX('DwC attribute vocabulary'!$D$3:$D$903,MATCH(B36,'DwC attribute vocabulary'!$C$3:$C$903, 0)) -> Organism Quantity | D36: Include if possible | E36: =INDEX('DwC attribute vocabulary'!$J$3:$J$903,MATCH(B36,'DwC attribute vocabulary'!$C$3:$C$903, 0)) -> recommended | F36: =INDEX('DwC attribute vocabulary'!$E$3:$E$903,MATCH(B36,'DwC attribute vocabulary'!$C$3:$C$903, 0)) -> A number or enumeration value for the quantity of organisms. | G36: =INDEX('DwC attribute vocabulary'!$F$3:$F$903,MATCH($B36,'DwC attribute vocabulary'!$C$3:$C$903, 0)) -> An organismQuantity must have a corresponding organismQuantityType. | H36: =INDEX('DwC attribute vocabulary'!$G$3:$G$903,MATCH($B36,'DwC attribute vocabulary'!$C$3:$C$903, 0)) -> `27` (organismQuantity) with `individuals` (organismQuantityType); `12.5` (organismQuantity) with `% biomass` (organismQuantityType); `r` (organismQuantity) with `Braun Blanquet Scale` (organismQuantityType); `many` (organismQuantity) with `individuals` (organismQuantityType)
A37: 27 | B37: organismQuantityType | C37: =INDEX('DwC attribute vocabulary'!$D$3:$D$903,MATCH(B37,'DwC attribute vocabulary'!$C$3:$C$903, 0)) -> Organism Quantity Type | D37: Include if possible | E37: =INDEX('DwC attribute vocabulary'!$J$3:$J$903,MATCH(B37,'DwC attribute vocabulary'!$C$3:$C$903, 0)) -> recommended | F37: =INDEX('DwC attribute vocabulary'!$E$3:$E$903,MATCH(B37,'DwC attribute vocabulary'!$C$3:$C$903, 0)) -> The type of quantification system used for the quantity of organisms. | G37: =INDEX('DwC attribute vocabulary'!$F$3:$F$903,MATCH($B37,'DwC attribute vocabulary'!$C$3:$C$903, 0)) -> A dwc:organismQuantityType must have a corresponding dwc:organismQuantity. | H37: =INDEX('DwC attribute vocabulary'!$G$3:$G$903,MATCH($B37,'DwC attribute vocabulary'!$C$3:$C$903, 0)) -> `27` (organismQuantity) with `individuals` (organismQuantityType); `12.5` (organismQuantity) with `% biomass` (organismQuantityType); `r` (organismQuantity) with `Braun Blanquet Scale` (organismQuantityType); `many` (organismQuantity) with `individuals` (organismQuantityType)
A38: 28 | B38: sex | C38: =INDEX('DwC attribute vocabulary'!$D$3:$D$903,MATCH(B38,'DwC attribute vocabulary'!$C$3:$C$903, 0)) -> Sex | E38: =INDEX('DwC attribute vocabulary'!$J$3:$J$903,MATCH(B38,'DwC attribute vocabulary'!$C$3:$C$903, 0)) -> recommended | F38: =INDEX('DwC attribute vocabulary'!$E$3:$E$903,MATCH(B38,'DwC attribute vocabulary'!$C$3:$C$903, 0)) -> The sex of the biological individual(s) represented in the Occurrence. | G38: =INDEX('DwC attribute vocabulary'!$F$3:$F$903,MATCH($B38,'DwC attribute vocabulary'!$C$3:$C$903, 0)) -> Recommended best practice is to use a controlled vocabulary. | H38: =INDEX('DwC attribute vocabulary'!$G$3:$G$903,MATCH($B38,'DwC attribute vocabulary'!$C$3:$C$903, 0)) -> `female`; `male`; `hermaphrodite`
A39: 29 | B39: lifeStage | C39: =INDEX('DwC attribute vocabulary'!$D$3:$D$903,MATCH(B39,'DwC attribute vocabulary'!$C$3:$C$903, 0)) -> Life Stage | D39: Include if possible | E39: =INDEX('DwC attribute vocabulary'!$J$3:$J$903,MATCH(B39,'DwC attribute vocabulary'!$C$3:$C$903, 0)) -> recommended | F39: =INDEX('DwC attribute vocabulary'!$E$3:$E$903,MATCH(B39,'DwC attribute vocabulary'!$C$3:$C$903, 0)) -> The age class or life stage of the Organism(s) at the time the Occurrence was recorded. | G39: =INDEX('DwC attribute vocabulary'!$F$3:$F$903,MATCH($B39,'DwC attribute vocabulary'!$C$3:$C$903, 0)) -> Recommended best practice is to use a controlled vocabulary. | H39: =INDEX('DwC attribute vocabulary'!$G$3:$G$903,MATCH($B39,'DwC attribute vocabulary'!$C$3:$C$903, 0)) -> `zygote`; `larva`; `juvenile`; `adult`; `seedling`; `flowering`; `fruiting`
A40: 30 | B40: reproductiveCondition | C40: =INDEX('DwC attribute vocabulary'!$D$3:$D$903,MATCH(B40,'DwC attribute vocabulary'!$C$3:$C$903, 0)) -> Reproductive Condition | E40: =INDEX('DwC attribute vocabulary'!$J$3:$J$903,MATCH(B40,'DwC attribute vocabulary'!$C$3:$C$903, 0)) -> recommended | F40: =INDEX('DwC attribute vocabulary'!$E$3:$E$903,MATCH(B40,'DwC attribute vocabulary'!$C$3:$C$903, 0)) -> The reproductive condition of the biological individual(s) represented in the Occurrence. | G40: =INDEX('DwC attribute vocabulary'!$F$3:$F$903,MATCH($B40,'DwC attribute vocabulary'!$C$3:$C$903, 0)) -> Recommended best practice is to use a controlled vocabulary. | H40: =INDEX('DwC attribute vocabulary'!$G$3:$G$903,MATCH($B40,'DwC attribute vocabulary'!$C$3:$C$903, 0)) -> `non-reproductive`; `pregnant`; `in bloom`; `fruit-bearing`
A41: 31 | B41: behavior | C41: =INDEX('DwC attribute vocabulary'!$D$3:$D$903,MATCH(B41,'DwC attribute vocabulary'!$C$3:$C$903, 0)) -> Behavior | E41: =INDEX('DwC attribute vocabulary'!$J$3:$J$903,MATCH(B41,'DwC attribute vocabulary'!$C$3:$C$903, 0)) -> recommended | F41: =INDEX('DwC attribute vocabulary'!$E$3:$E$903,MATCH(B41,'DwC attribute vocabulary'!$C$3:$C$903, 0)) -> The behavior shown by the subject at the time the Occurrence was recorded. | G41: =INDEX('DwC attribute vocabulary'!$F$3:$F$903,MATCH($B41,'DwC attribute vocabulary'!$C$3:$C$903, 0)) -> 0 | H41: =INDEX('DwC attribute vocabulary'!$G$3:$G$903,MATCH($B41,'DwC attribute vocabulary'!$C$3:$C$903, 0)) -> `roosting`; `foraging`; `running`
...

Sheet DwC attribute vocabulary
B1: La siguiente lista de términos del Darwin Core Standard fue obtenida de https://github.com/tdwg/dwc/tree/4e919e11fc9bc342a3a987cf311abc810617ff2d (acceso, 2023-04-28).
B2: iri | C2: term_localName | D2: label | E2: definition | F2: comments | G2: examples | H2: organized_in | I2: issued | J2: status | K2: replaces | L2: rdf_type | M2: term_iri | N2: abcd_equivalence | O2: flags
A3: 1 | B3: http://dublincore.org/usage/terms/history/#type-006 | C3: type | D3: Type | E3: The nature or genre of the resource. | F3: Must be populated with a value from the DCMI type vocabulary (http://dublincore.org/documents/2010/10/11/dcmi-type-vocabulary/). | G3: `StillImage`; `MovingImage`; `Sound`; `PhysicalObject`; `Event`; `Text` | H3: http://purl.org/dc/elements/1.1/ | I3: 2008-01-14 | J3: recommended | K3: http://dublincore.org/usage/terms/history/#typeT-001 | L3: http://www.w3.org/1999/02/22-rdf-syntax-ns#Property | M3: http://purl.org/dc/elements/1.1/type | N3: not in ABCD | O3: simple
A4: 2 | B4: http://dublincore.org/usage/terms/history/#modified-003 | C4: modified | D4: Date Modified | E4: The most recent date-time on which the resource was changed. | F4: Recommended best practice is to use a date that conforms to ISO 8601-1:2019. | G4: `1963-03-08T14:07-0600` (8 Mar 1963 at 2:07pm in the time zone six hours earlier than UTC); `2009-02-20T08:40Z` (20 February 2009 8:40am UTC); `2018-08-29T15:19` (3:19pm local time on 29 August 2018); `1809-02-12` (some time during 12 February 1809); `1906-06` (some time in June 1906); `1971` (some time in the year 1971); `2007-03-01T13:00:00Z/2008-05-11T15:30:00Z` (some time during the interval between 1 March 2007 1pm UTC and 11 May 2008 3:30pm UTC); `1900/1909` (some time during the interval between the beginning of the year 1900 and the end of the year 1909); `2007-11-13/15` (some time in the interval between 13 November 2007 and 15 November 2007) | H4: http://purl.org/dc/terms/ | I4: 2008-01-14 | J4: recommended | L4: http://www.w3.org/1999/02/22-rdf-syntax-ns#Property | M4: http://purl.org/dc/terms/modified | N4: not in ABCD | O4: simple
A5: 3 | B5: http://dublincore.org/usage/terms/history/#language-007 | C5: language | D5: Language | E5: A language of the resource. | F5: Recommended best practice is to use a controlled vocabulary such as RFC 5646. | G5: `en` (for English); `es` (for Spanish) | H5: http://purl.org/dc/elements/1.1/ | I5: 2008-01-14 | J5: recommended | K5: http://dublincore.org/usage/terms/history/#languageT-001 | L5: http://www.w3.org/1999/02/22-rdf-syntax-ns#Property | M5: http://purl.org/dc/elements/1.1/language | N5: not in ABCD | O5: simple
A6: 4 | B6: http://dublincore.org/usage/terms/history/#license-002 | C6: license | D6: License | E6: A legal document giving official permission to do something with the resource. | G6: `http://creativecommons.org/publicdomain/zero/1.0/legalcode`; `http://creativecommons.org/licenses/by/4.0/legalcode` | H6: http://purl.org/dc/terms/ | I6: 2008-01-14 | J6: recommended | K6: http://dublincore.org/usage/terms/history/#rightsT-001 | L6: http://www.w3.org/1999/02/22-rdf-syntax-ns#Property | M6: http://purl.org/dc/terms/license | N6: not in ABCD | O6: simple
A7: 5 | B7: http://dublincore.org/usage/terms/history/#rightsHolder-002 | C7: rightsHolder | D7: Rights Holder | E7: A person or organization owning or managing rights over the resource. | G7: `The Regents of the University of California` | H7: http://purl.org/dc/terms/ | I7: 2008-01-14 | J7: recommended | L7: http://www.w3.org/1999/02/22-rdf-syntax-ns#Property | M7: http://purl.org/dc/terms/rightsHolder | N7: not in ABCD | O7: simple
A8: 6 | B8: http://dublincore.org/usage/terms/history/#accessRights-002 | C8: accessRights | D8: Access Rights | E8: Information about who can access the resource or an indication of its security status. | F8: Access Rights may include information regarding access or restrictions based on privacy, security, or other policies. | G8: `not-for-profit use only`; `https://www.fieldmuseum.org/field-museum-natural-history-conditions-and-suggested-norms-use-collections-data-and-images` | H8: http://purl.org/dc/terms/ | I8: 2008-01-14 | J8: recommended | K8: http://rs.tdwg.org/dwc/terms/version/AccessConstraints-2008-11-19 | L8: http://www.w3.org/1999/02/22-rdf-syntax-ns#Property | M8: http://purl.org/dc/terms/accessRights | N8: not in ABCD | O8: simple
A9: 7 | B9: http://dublincore.org/usage/terms/history/#bibliographicCitation-002 | C9: bibliographicCitation | D9: Bibliographic Citation | E9: A bibliographic reference for the resource as a statement indicating how this record should be cited (attributed) when used. | F9: From Dublin Core, "Recommended practice is to include sufficient bibliographic detail to identify the resource as unambiguously as possible." The intended usage of this term in Darwin Core is to provide the preferred way to cite the resource itself - "how to cite this record". Note that the intended usage of dcterms:references in Darwin Core, by contrast, is to point to the definitive source representation of the resource - "where to find the as-close-to-original reference, if one is available. | G9: Occurrence example: `Museum of Vertebrate Zoology, UC Berkeley. MVZ Mammal Collection (Arctos). Record ID: http://arctos.database.museum/guid/MVZ:Mamm:165861?seid=101356. Source: http://ipt.vertnet.org:8080/ipt/resource.do?r=mvz_mammal.`; Taxon example: `https://www.gbif.org/species/2439608 Source: GBIF Taxonomic Backbone`; Event example: `Rand, K.M., Logerwell, E.A. The first demersal trawl survey of benthic fish and invertebrates in the Beaufort Sea since the late 1970s. Polar Biol 34, 475–488 (2011). https://doi.org/10.1007/s00300-010-0900-2` | H9: http://purl.org/dc/terms/ | I9: 2008-01-14 | J9: recommended | L9: http://www.w3.org/1999/02/22-rdf-syntax-ns#Property | M9: http://purl.org/dc/terms/bibliographicCitation | N9: not in ABCD | O9: simple
A10: 8 | B10: http://dublincore.org/usage/terms/history/#references-003 | C10: references | D10: References | E10: A related resource that is referenced, cited, or otherwise pointed to by the described resource. | F10: From Dublin Core, "This property is intended to be used with non-literal values. This property is an inverse property of Is Referenced By." The intended usage of this term in Darwin Core is to point to the definitive source representation of the resource (e.g., Taxon, Occurrence, Event in Darwin Core), if one is available. Note that the intended usage of dcterms:bibliographicCitation in Darwin Core, by contrast, is to provide the preferred way to cite the resource itself. | G10: MaterialSample example: `http://arctos.database.museum/guid/MVZ:Mamm:165861`; Taxon example: `https://www.catalogueoflife.org/data/taxon/32664` | H10: http://purl.org/dc/terms/ | I10: 2008-01-14 | J10: recommended | L10: http://www.w3.org/1999/02/22-rdf-syntax-ns#Property | M10: http://purl.org/dc/terms/references | N10: not in ABCD | O10: simple
A11: 9 | B11: http://rs.tdwg.org/dwc/terms/version/institutionID-2017-10-06 | C11: institutionID | D11: Institution ID | E11: An identifier for the institution having custody of the object(s) or information referred to in the record. | F11: For physical specimens, the recommended best practice is to use an identifier from a collections registry such as the Global Registry of Biodiversity Repositories (http://grbio.org/). | G11: `http://biocol.org/urn:lsid:biocol.org:col:34777`; `http://grbio.org/cool/km06-gtbn` | H11: http://rs.tdwg.org/dwc/terms/ | I11: 2017-10-06 | J11: recommended | K11: http://rs.tdwg.org/dwc/terms/version/institutionID-2009-09-11 | L11: http://www.w3.org/1999/02/22-rdf-syntax-ns#Property | M11: http://rs.tdwg.org/dwc/terms/institutionID | N11: DataSets/DataSet/Units/Unit/SourceInstitutionID | O11: simple
A12: 10 | B12: http://rs.tdwg.org/dwc/terms/version/collectionID-2017-10-06 | C12: collectionID | D12: Collection ID | E12: An identifier for the collection or dataset from which the record was derived. | F12: For physical specimens, the recommended best practice is to use an identifier from a collections registry such as the Global Registry of Biodiversity Repositories (http://grbio.org/). | G12: `http://biocol.org/urn:lsid:biocol.org:col:1001`; `http://grbio.org/cool/p5fp-c036` | H12: http://rs.tdwg.org/dwc/terms/ | I12: 2017-10-06 | J12: recommended | K12: http://rs.tdwg.org/dwc/terms/version/collectionID-2009-09-11 | L12: http://www.w3.org/1999/02/22-rdf-syntax-ns#Property | M12: http://rs.tdwg.org/dwc/terms/collectionID | N12: DataSets/DataSet/Units/Unit/SourceID | O12: simple
A13: 11 | B13: http://rs.tdwg.org/dwc/terms/version/datasetID-2017-10-06 | C13: datasetID | D13: Dataset ID | E13: An identifier for the set of data. May be a global unique identifier or an identifier specific to a collection or institution. | G13: `b15d4952-7d20-46f1-8a3e-556a512b04c5` | H13: http://rs.tdwg.org/dwc/terms/ | I13: 2017-10-06 | J13: recommended | K13: http://rs.tdwg.org/dwc/terms/version/datasetID-2009-09-11 | L13: http://www.w3.org/1999/02/22-rdf-syntax-ns#Property | M13: http://rs.tdwg.org/dwc/terms/datasetID | N13: DataSets/DataSet/DataSetGUID | O13: simple
A14: 12 | B14: http://rs.tdwg.org/dwc/terms/version/institutionCode-2017-10-06 | C14: institutionCode | D14: Institution Code | E14: The name (or acronym) in use by the institution having custody of the object(s) or information referred to in the record. | G14: `MVZ`; `FMNH`; `CLO`; `UCMP` | H14: http://rs.tdwg.org/dwc/terms/ | I14: 2017-10-06 | J14: recommended | K14: http://rs.tdwg.org/dwc/terms/version/institutionCode-2009-09-11 | L14: http://www.w3.org/1999/02/22-rdf-syntax-ns#Property | M14: http://rs.tdwg.org/dwc/terms/institutionCode | N14: DataSets/DataSet/Units/Unit/SourceInstitutionID | O14: simple
A15: 13 | B15: http://rs.tdwg.org/dwc/terms/version/collectionCode-2017-10-06 | C15: collectionCode | D15: Collection Code | E15: The name, acronym, coden, or initialism identifying the collection or data set from which the record was derived. | G15: `Mammals`; `Hildebrandt`; `EBIRD`; `VP` | H15: http://rs.tdwg.org/dwc/terms/ | I15: 2017-10-06 | J15: recommended | K15: http://rs.tdwg.org/dwc/terms/version/collectionCode-2009-09-11 | L15: http://www.w3.org/1999/02/22-rdf-syntax-ns#Property | M15: http://rs.tdwg.org/dwc/terms/collectionCode | N15: DataSets/DataSet/Units/Unit/SourceID | O15: simple
A16: 14 | B16: http://rs.tdwg.org/dwc/terms/version/datasetName-2017-10-06 | C16: datasetName | D16: Dataset Name | E16: The name identifying the data set from which the record was derived. | G16: `Grinnell Resurvey Mammals`; `Lacey Ctenomys Recaptures` | H16: http://rs.tdwg.org/dwc/terms/ | I16: 2017-10-06 | J16: recommended | K16: http://rs.tdwg.org/dwc/terms/version/datasetName-2009-09-11 | L16: http://www.w3.org/1999/02/22-rdf-syntax-ns#Property | M16: http://rs.tdwg.org/dwc/terms/datasetName | N16: DataSets/DataSet/Units/Unit/SourceID | O16: simple
A17: 15 | B17: http://rs.tdwg.org/dwc/terms/version/ownerInstitutionCode-2017-10-06 | C17: ownerInstitutionCode | D17: Owner Institution Code | E17: The name (or acronym) in use by the institution having ownership of the object(s) or information referred to in the record. | G17: `NPS`; `APN`; `InBio` | H17: http://rs.tdwg.org/dwc/terms/ | I17: 2017-10-06 | J17: recommended | K17: http://rs.tdwg.org/dwc/terms/version/ownerInstitutionCode-2009-08-24 | L17: http://www.w3.org/1999/02/22-rdf-syntax-ns#Property | M17: http://rs.tdwg.org/dwc/terms/ownerInstitutionCode | N17: not in ABCD | O17: simple
A18: 16 | B18: http://rs.tdwg.org/dwc/terms/version/basisOfRecord-2021-07-15 | C18: basisOfRecord | D18: Basis of Record | E18: The specific nature of the data record. | F18: Recommended best practice is to use the standard label of one of the Darwin Core classes. | G18: `PreservedSpecimen`; `FossilSpecimen`; `LivingSpecimen`; `MaterialSample`; `Event`; `HumanObservation`; `MachineObservation`; `Taxon`; `Occurrence`; `MaterialCitation` | H18: http://rs.tdwg.org/dwc/terms/ | I18: 2021-07-15 | J18: recommended | K18: http://rs.tdwg.org/dwc/terms/version/basisOfRecord-2017-10-06 | L18: http://www.w3.org/1999/02/22-rdf-syntax-ns#Property | M18: http://rs.tdwg.org/dwc/terms/basisOfRecord | N18: DataSets/DataSet/Units/Unit/RecordBasis | O18: simple
A19: 17 | B19: http://rs.tdwg.org/dwc/terms/version/informationWithheld-2017-10-06 | C19: informationWithheld | D19: Information Withheld | E19: Additional information that exists, but that has not been shared in the given record. | G19: `location information not given for endangered species`; `collector identities withheld | ask about tissue samples` | H19: http://rs.tdwg.org/dwc/terms/ | I19: 2017-10-06 | J19: recommended | K19: http://rs.tdwg.org/dwc/terms/version/informationWithheld-2009-04-24 | L19: http://www.w3.org/1999/02/22-rdf-syntax-ns#Property | M19: http://rs.tdwg.org/dwc/terms/informationWithheld | N19: DataSets/DataSet/Units/Unit/InformationWithheld | O19: simple
A20: 18 | B20: http://rs.tdwg.org/dwc/terms/version/dataGeneralizations-2017-10-06 | C20: dataGeneralizations | D20: Data Generalizations | E20: Actions taken to make the shared data less specific or complete than in its original form. Suggests that alternative data of higher quality may be available on request. | G20: `Coordinates generalized from original GPS coordinates to the nearest half degree grid cell` | H20: http://rs.tdwg.org/dwc/terms/ | I20: 2017-10-06 | J20: recommended | K20: http://rs.tdwg.org/dwc/terms/version/dataGeneralizations-2009-04-24 | L20: http://www.w3.org/1999/02/22-rdf-syntax-ns#Property | M20: http://rs.tdwg.org/dwc/terms/dataGeneralizations | N20: not in ABCD | O20: simple
A21: 19 | B21: http://rs.tdwg.org/dwc/terms/version/dynamicProperties-2017-10-06 | C21: dynamicProperties | D21: Dynamic Properties | E21: A list of additional measurements, facts, characteristics, or assertions about the record. Meant to provide a mechanism for structured content. | F21: Recommended best practice is to use a key:value encoding schema for a data interchange format such as JSON. | G21: `{"heightInMeters":1.5}`; `{"tragusLengthInMeters":0.014, "weightInGrams":120}`; `{"natureOfID":"expert identification", "identificationEvidence":"cytochrome B sequence"}`; `{"relativeHumidity":28, "airTemperatureInCelsius":22, "sampleSizeInKilograms":10}`; `{"aspectHeading":277, "slopeInDegrees":6}`; `{"iucnStatus":"vulnerable", "taxonDistribution":"Neuquén, Argentina"}` | H21: http://rs.tdwg.org/dwc/terms/ | I21: 2017-10-06 | J21: recommended | K21: http://rs.tdwg.org/dwc/terms/version/dynamicProperties-2014-10-23 | L21: http://www.w3.org/1999/02/22-rdf-syntax-ns#Property | M21: http://rs.tdwg.org/dwc/terms/dynamicProperties | N21: not in ABCD | O21: simple
A22: 20 | B22: http://rs.tdwg.org/dwc/terms/version/Occurrence-2020-08-20 | C22: Occurrence | D22: Occurrence | E22: An existence of an Organism (sensu http://rs.tdwg.org/dwc/terms/Organism) at a particular place at a particular time. | G22: A wolf pack on the shore of Kluane Lake in 1988. A virus in a plant leaf in the New York Botanical Garden at 15:29 on 2014-10-23. A fungus in Central Park in the summer of 1929. | I22: 2020-08-20 | J22: recommended | K22: http://rs.tdwg.org/dwc/terms/version/Occurrence-2018-09-06 | L22: http://www.w3.org/2000/01/rdf-schema#Class | M22: http://rs.tdwg.org/dwc/terms/Occurrence | N22: DataSets/DataSet/Units/Unit | O22: extension
A23: 21 | B23: http://rs.tdwg.org/dwc/terms/version/occurrenceID-2017-10-06 | C23: occurrenceID | D23: Occurrence ID | E23: An identifier for the Occurrence (as opposed to a particular digital record of the occurrence). In the absence of a persistent global unique identifier, construct one from a combination of identifiers in the record that will most closely make the occurrenceID globally unique. | F23: Recommended best practice is to use a persistent, globally unique identifier. | G23: `http://arctos.database.museum/guid/MSB:Mamm:233627`; `000866d2-c177-4648-a200-ead4007051b9`; `urn:catalog:UWBM:Bird:89776` | H23: http://rs.tdwg.org/dwc/terms/Occurrence | I23: 2017-10-06 | J23: recommended | K23: http://rs.tdwg.org/dwc/terms/version/occurrenceID-2009-04-24 | L23: http://www.w3.org/1999/02/22-rdf-syntax-ns#Property | M23: http://rs.tdwg.org/dwc/terms/occurrenceID | N23: DataSets/DataSet/Units/Unit/UnitGUID | O23: simple
A24: 22 | B24: http://rs.tdwg.org/dwc/terms/version/catalogNumber-2017-10-06 | C24: catalogNumber | D24: Catalog Number | E24: An identifier (preferably unique) for the record within the data set or collection. | G24: `145732`; `145732a`; `2008.1334`; `R-4313` | H24: http://rs.tdwg.org/dwc/terms/Occurrence | I24: 2017-10-06 | J24: recommended | K24: http://rs.tdwg.org/dwc/terms/version/catalogNumber-2009-04-24 | L24: http://www.w3.org/1999/02/22-rdf-syntax-ns#Property | M24: http://rs.tdwg.org/dwc/terms/catalogNumber | N24: DataSets/DataSet/Units/Unit/UnitID | O24: simple
A25: 23 | B25: http://rs.tdwg.org/dwc/terms/version/recordNumber-2017-10-06 | C25: recordNumber | D25: Record Number | E25: An identifier given to the Occurrence at the time it was recorded. Often serves as a link between field notes and an Occurrence record, such as a specimen collector's number. | G25: `OPP 7101` | H25: http://rs.tdwg.org/dwc/terms/Occurrence | I25: 2017-10-06 | J25: recommended | K25: http://rs.tdwg.org/dwc/terms/version/recordNumber-2009-04-24 | L25: http://www.w3.org/1999/02/22-rdf-syntax-ns#Property | M25: http://rs.tdwg.org/dwc/terms/recordNumber | N25: DataSets/DataSet/Units/Unit/CollectorsFieldNumber | O25: simple
A26: 24 | B26: http://rs.tdwg.org/dwc/terms/version/recordedBy-2017-10-06 | C26: recordedBy | D26: Recorded By | E26: A list (concatenated and separated) of names of people, groups, or organizations responsible for recording the original Occurrence. The primary collector or observer, especially one who applies a personal identifier (recordNumber), should be listed first. | F26: Recommended best practice is to separate the values in a list with space vertical bar space (` | `). | G26: `José E. Crespo`; `Oliver P. Pearson | Anita K. Pearson` (where the value in recordNumber `OPP 7101` corresponds to the collector number for the specimen in the field catalog of Oliver P. Pearson) | H26: http://rs.tdwg.org/dwc/terms/Occurrence | I26: 2017-10-06 | J26: recommended | K26: http://rs.tdwg.org/dwc/terms/version/recordedBy-2014-10-23 | L26: http://www.w3.org/1999/02/22-rdf-syntax-ns#Property | M26: http://rs.tdwg.org/dwc/terms/recordedBy | N26: DataSets/DataSet/Units/Unit/Gathering/GatheringAgents/GatheringAgentsText | O26: simple
A27: 25 | B27: http://rs.tdwg.org/dwc/terms/version/recordedByID-2021-07-15 | C27: recordedByID | D27: Recorded By ID | E27: A list (concatenated and separated) of the globally unique identifier for the person, people, groups, or organizations responsible for recording the original Occurrence. | F27: Recommended best practice is to provide a single identifier that disambiguates the details of the identifying agent. If a list is used, it is recommended to separate the values in the list with space vertical bar space (` | `). The order of the identifiers on any list for this term can not be guaranteed to convey any semantics. | G27: `https://orcid.org/0000-0002-1825-0097` (for an individual); `https://orcid.org/0000-0002-1825-0097 | https://orcid.org/0000-0002-1825-0098` (for a list of people) | H27: http://rs.tdwg.org/dwc/terms/Occurrence | I27: 2021-07-15 | J27: recommended | L27: http://www.w3.org/1999/02/22-rdf-syntax-ns#Property | M27: http://rs.tdwg.org/dwc/terms/recordedByID | N27: not in ABCD | O27: simple
A28: 26 | B28: http://rs.tdwg.org/dwc/terms/version/individualCount-2021-07-15 | C28: individualCount | D28: Individual Count | E28: The number of individuals present at the time of the Occurrence. | G28: `0`; `1`; `25` | H28: http://rs.tdwg.org/dwc/terms/Occurrence | I28: 2021-07-15 | J28: recommended | K28: http://rs.tdwg.org/dwc/terms/version/individualCount-2017-10-06 | L28: http://www.w3.org/1999/02/22-rdf-syntax-ns#Property | M28: http://rs.tdwg.org/dwc/terms/individualCount | N28: DataSets/DataSet/Units/Unit/Gathering/SiteMeasurementsOrFacts/SiteMeasurementOrFact/MeasurementOrFactAtomised/LowerValue | O28: simple
A29: 27 | B29: http://rs.tdwg.org/dwc/terms/version/organismQuantity-2021-07-15 | C29: organismQuantity | D29: Organism Quantity | E29: A number or enumeration value for the quantity of organisms. | F29: An organismQuantity must have a corresponding organismQuantityType. | G29: `27` (organismQuantity) with `individuals` (organismQuantityType); `12.5` (organismQuantity) with `% biomass` (organismQuantityType); `r` (organismQuantity) with `Braun Blanquet Scale` (organismQuantityType); `many` (organismQuantity) with `individuals` (organismQuantityType) | H29: http://rs.tdwg.org/dwc/terms/Occurrence | I29: 2021-07-15 | J29: recommended | K29: http://rs.tdwg.org/dwc/terms/version/organismQuantity-2017-10-06 | L29: http://www.w3.org/1999/02/22-rdf-syntax-ns#Property | M29: http://rs.tdwg.org/dwc/terms/organismQuantity | N29: not in ABCD | O29: simple
A30: 28 | B30: http://rs.tdwg.org/dwc/terms/version/organismQuantityType-2017-10-06 | C30: organismQuantityType | D30: Organism Quantity Type | E30: The type of quantification system used for the quantity of organisms. | F30: A dwc:organismQuantityType must have a corresponding dwc:organismQuantity. | G30: `27` (organismQuantity) with `individuals` (organismQuantityType); `12.5` (organismQuantity) with `% biomass` (organismQuantityType); `r` (organismQuantity) with `Braun Blanquet Scale` (organismQuantityType); `many` (organismQuantity) with `individuals` (organismQuantityType) | H30: http://rs.tdwg.org/dwc/terms/Occurrence | I30: 2017-10-06 | J30: recommended | K30: http://rs.tdwg.org/dwc/terms/version/organismQuantityType-2014-12-23 | L30: http://www.w3.org/1999/02/22-rdf-syntax-ns#Property | M30: http://rs.tdwg.org/dwc/terms/organismQuantityType | N30: not in ABCD | O30: simple
A31: 29 | B31: http://rs.tdwg.org/dwc/terms/version/sex-2017-10-06 | C31: sex | D31: Sex | E31: The sex of the biological individual(s) represented in the Occurrence. | F31: Recommended best practice is to use a controlled vocabulary. | G31: `female`; `male`; `hermaphrodite` | H31: http://rs.tdwg.org/dwc/terms/Occurrence | I31: 2017-10-06 | J31: recommended | K31: http://rs.tdwg.org/dwc/terms/version/sex-2009-04-24 | L31: http://www.w3.org/1999/02/22-rdf-syntax-ns#Property | M31: http://rs.tdwg.org/dwc/terms/sex | N31: DataSets/DataSet/Units/Unit/Sex | O31: simple
A32: 30 | B32: http://rs.tdwg.org/dwc/terms/version/lifeStage-2021-07-15 | C32: lifeStage | D32: Life Stage | E32: The age class or life stage of the Organism(s) at the time the Occurrence was recorded. | F32: Recommended best practice is to use a controlled vocabulary. | G32: `zygote`; `larva`; `juvenile`; `adult`; `seedling`; `flowering`; `fruiting` | H32: http://rs.tdwg.org/dwc/terms/Occurrence | I32: 2021-07-15 | J32: recommended | K32: http://rs.tdwg.org/dwc/terms/version/lifeStage-2017-10-06 | L32: http://www.w3.org/1999/02/22-rdf-syntax-ns#Property | M32: http://rs.tdwg.org/dwc/terms/lifeStage | N32: DataSets/DataSet/Units/Unit/MycologicalUnit/MycologicalSexualStage or DataSets/DataSet/Units/Unit/MycologicalUnit/MycologicalLiveStages/MycologicalLiveStage or DataSets/DataSet/Units/Unit/ZoologicalUnit/PhasesOrStages/PhaseOrStage | O32: simple
A33: 31 | B33: http://rs.tdwg.org/dwc/terms/version/reproductiveCondition-2017-10-06 | C33: reproductiveCondition | D33: Reproductive Condition | E33: The reproductive condition of the biological individual(s) represented in the Occurrence. | F33: Recommended best practice is to use a controlled vocabulary. | G33: `non-reproductive`; `pregnant`; `in bloom`; `fruit-bearing` | H33: http://rs.tdwg.org/dwc/terms/Occurrence | I33: 2017-10-06 | J33: recommended | K33: http://rs.tdwg.org/dwc/terms/version/reproductiveCondition-2009-04-24 | L33: http://www.w3.org/1999/02/22-rdf-syntax-ns#Property | M33: http://rs.tdwg.org/dwc/terms/reproductiveCondition | N33: not in ABCD | O33: simple
A34: 32 | B34: http://rs.tdwg.org/dwc/terms/version/behavior-2017-10-06 | C34: behavior | D34: Behavior | E34: The behavior shown by the subject at the time the Occurrence was recorded. | G34: `roosting`; `foraging`; `running` | H34: http://rs.tdwg.org/dwc/terms/Occurrence | I34: 2017-10-06 | J34: recommended | K34: http://rs.tdwg.org/dwc/terms/version/behavior-2009-04-24 | L34: http://www.w3.org/1999/02/22-rdf-syntax-ns#Property | M34: http://rs.tdwg.org/dwc/terms/behavior | N34: not in ABCD | O34: simple
A35: 33 | B35: http://rs.tdwg.org/dwc/terms/version/establishmentMeans-2021-03-29 | C35: establishmentMeans | D35: Establishment Means | E35: Statement about whether an organism or organisms have been introduced to a given place and time through the direct or indirect activity of modern humans. | F35: Recommended best practice is to use controlled value strings from the controlled vocabulary designated for use with this term, listed at http://rs.tdwg.org/dwc/doc/em/. For details, refer to https://doi.org/10.3897/biss.3.38084 | G35: `native`; `nativeReintroduced`; `introduced`; `introducedAssistedColonisation`; `vagrant`; `uncertain` | H35: http://rs.tdwg.org/dwc/terms/Occurrence | I35: 2021-03-29 | J35: recommended | K35: http://rs.tdwg.org/dwc/terms/version/establishmentMeans-2020-10-28 | L35: http://www.w3.org/1999/02/22-rdf-syntax-ns#Property | M35: http://rs.tdwg.org/dwc/terms/establishmentMeans | N35: DataSets/DataSet/Units/Unit/Gathering/EstablishmentMeans | O35: simple
A36: 34 | B36: http://rs.tdwg.org/dwc/terms/version/degreeOfEstablishment-2021-03-29 | C36: degreeOfEstablishment | D36: Degree of Establishment | E36: The degree to which an Organism survives, reproduces, and expands its range at the given place and time. | F36: Recommended best practice is to use controlled value strings from the controlled vocabulary designated for use with this term, listed at http://rs.tdwg.org/dwc/doc/doe/. For details, refer to https://doi.org/10.3897/biss.3.38084 | G36: `native`; `captive`; `cultivated`; `released`; `failing`; `casual`; `reproducing`; `established`; `colonising`; `invasive`; `widespreadInvasive` | H36: http://rs.tdwg.org/dwc/terms/Occurrence | I36: 2021-03-29 | J36: recommended | K36: http://rs.tdwg.org/dwc/terms/version/degreeOfEstablishment-2020-10-13 | L36: http://www.w3.org/1999/02/22-rdf-syntax-ns#Property | M36: http://rs.tdwg.org/dwc/terms/degreeOfEstablishment | O36: simple
A37: 35 | B37: http://rs.tdwg.org/dwc/terms/version/pathway-2021-03-29 | C37: pathway | D37: Pathway | E37: The process by which an Organism came to be in a given place at a given time. | F37: Recommended best practice is to use controlled value strings from the controlled vocabulary designated for use with this term, listed at http://rs.tdwg.org/dwc/doc/pw/. For details, refer to https://doi.org/10.3897/biss.3.38084 | G37: `releasedForUse`; `otherEscape`; `transportContaminant`; `transportStowaway`; `corridor`; `unaided` | H37: http://rs.tdwg.org/dwc/terms/Occurrence | I37: 2021-03-29 | J37: recommended | K37: http://rs.tdwg.org/dwc/terms/version/pathway-2020-10-13 | L37: http://www.w3.org/1999/02/22-rdf-syntax-ns#Property | M37: http://rs.tdwg.org/dwc/terms/pathway | O37: simple
